2016-01-28 15:47:14,310 - util.py[DEBUG]: Cloud-init v. 0.7.5 running 'init-local' at Thu, 28 Jan 2016 15:47:14 +0000. Up 18.50 seconds.
2016-01-28 15:47:14,313 - util.py[DEBUG]: Writing to /var/log/cloud-init.log - ab: [420] 0 bytes
2016-01-28 15:47:14,313 - util.py[DEBUG]: Changing the ownership of /var/log/cloud-init.log to 101:4
2016-01-28 15:47:14,314 - util.py[DEBUG]: Attempting to remove /var/lib/cloud/instance/boot-finished
2016-01-28 15:47:14,314 - util.py[DEBUG]: Attempting to remove /var/lib/cloud/instance
2016-01-28 15:47:14,314 - util.py[DEBUG]: Attempting to remove /var/lib/cloud/data/no-net
2016-01-28 15:47:14,314 - util.py[DEBUG]: Reading from /var/lib/cloud/instance/obj.pkl (quiet=False)
2016-01-28 15:47:14,315 - importer.py[DEBUG]: Looking for modules ['ubuntu', 'cloudinit.distros.ubuntu'] that have attributes ['Distro']
2016-01-28 15:47:14,315 - importer.py[DEBUG]: Failed at attempted import of 'ubuntu' due to: No module named ubuntu
2016-01-28 15:47:14,317 - importer.py[DEBUG]: Found ubuntu with attributes ['Distro'] in ['cloudinit.distros.ubuntu']
2016-01-28 15:47:14,317 - stages.py[DEBUG]: Using distro class <class 'cloudinit.distros.ubuntu.Distro'>
2016-01-28 15:47:14,318 - __init__.py[DEBUG]: Looking for for data source in: ['ConfigDrive', 'None'], via packages ['', 'cloudinit.sources'] that matches dependencies ['FILESYSTEM']
2016-01-28 15:47:14,318 - importer.py[DEBUG]: Looking for modules ['DataSourceConfigDrive', 'cloudinit.sources.DataSourceConfigDrive'] that have attributes ['get_datasource_list']
2016-01-28 15:47:14,318 - importer.py[DEBUG]: Failed at attempted import of 'DataSourceConfigDrive' due to: No module named DataSourceConfigDrive
2016-01-28 15:47:14,321 - importer.py[DEBUG]: Found DataSourceConfigDrive with attributes ['get_datasource_list'] in ['cloudinit.sources.DataSourceConfigDrive']
2016-01-28 15:47:14,321 - importer.py[DEBUG]: Looking for modules ['DataSourceNone', 'cloudinit.sources.DataSourceNone'] that have attributes ['get_datasource_list']
2016-01-28 15:47:14,321 - importer.py[DEBUG]: Failed at attempted import of 'DataSourceNone' due to: No module named DataSourceNone
2016-01-28 15:47:14,322 - importer.py[DEBUG]: Found DataSourceNone with attributes ['get_datasource_list'] in ['cloudinit.sources.DataSourceNone']
2016-01-28 15:47:14,322 - __init__.py[DEBUG]: Searching for data source in: ['DataSourceConfigDrive']
2016-01-28 15:47:14,322 - __init__.py[DEBUG]: Seeing if we can get any data from <class 'cloudinit.sources.DataSourceConfigDrive.DataSourceConfigDrive'>
2016-01-28 15:47:14,322 - util.py[DEBUG]: Running command ['blkid', '-odevice', '/dev/sr0'] with allowed return codes [0, 2] (shell=False, capture=True)
2016-01-28 15:47:14,325 - util.py[DEBUG]: Running command ['blkid', '-odevice', '/dev/sr1'] with allowed return codes [0, 2] (shell=False, capture=True)
2016-01-28 15:47:14,327 - util.py[DEBUG]: Running command ['blkid', '-tTYPE=vfat', '-odevice'] with allowed return codes [0, 2] (shell=False, capture=True)
2016-01-28 15:47:14,348 - util.py[DEBUG]: Running command ['blkid', '-tTYPE=iso9660', '-odevice'] with allowed return codes [0, 2] (shell=False, capture=True)
2016-01-28 15:47:14,351 - util.py[DEBUG]: Running command ['blkid', '-tLABEL=config-2', '-odevice'] with allowed return codes [0, 2] (shell=False, capture=True)
2016-01-28 15:47:14,353 - util.py[DEBUG]: Reading from /proc/mounts (quiet=False)
2016-01-28 15:47:14,353 - util.py[DEBUG]: Read 915 bytes from /proc/mounts
2016-01-28 15:47:14,353 - util.py[DEBUG]: Fetched {'none': {'mountpoint': '/proc/xen', 'opts': 'rw,relatime', 'fstype': 'xenfs'}, 'devpts': {'mountpoint': '/dev/pts', 'opts': 'rw,nosuid,noexec,relatime,gid=5,mode=620,ptmxmode=000', 'fstype': 'devpts'}, 'sysfs': {'mountpoint': '/sys', 'opts': 'rw,nosuid,nodev,noexec,relatime', 'fstype': 'sysfs'}, 'udev': {'mountpoint': '/dev', 'opts': 'rw,relatime,size=495240k,nr_inodes=123810,mode=755', 'fstype': 'devtmpfs'}, '/dev/xvda1': {'mountpoint': '/', 'opts': 'rw,noatime,nobarrier,errors=remount-ro,data=ordered', 'fstype': 'ext4'}, 'tmpfs': {'mountpoint': '/run', 'opts': 'rw,nosuid,noexec,relatime,size=101224k,mode=755', 'fstype': 'tmpfs'}, 'proc': {'mountpoint': '/proc', 'opts': 'rw,nosuid,nodev,noexec,relatime', 'fstype': 'proc'}, 'rootfs': {'mountpoint': '/', 'opts': 'rw', 'fstype': 'rootfs'}} mounts from proc
2016-01-28 15:47:14,354 - util.py[DEBUG]: Running command ['mount', '-o', 'ro,sync', '/dev/xvdd', '/tmp/tmpyDKB3M'] with allowed return codes [0] (shell=False, capture=True)
2016-01-28 15:47:14,388 - util.py[DEBUG]: Reading from /tmp/tmpyDKB3M/openstack/2012-08-10/user_data (quiet=False)
2016-01-28 15:47:14,389 - util.py[DEBUG]: Read 3923 bytes from /tmp/tmpyDKB3M/openstack/2012-08-10/user_data
2016-01-28 15:47:14,389 - util.py[DEBUG]: Reading from /tmp/tmpyDKB3M/openstack/2012-08-10/meta_data.json (quiet=False)
2016-01-28 15:47:14,390 - util.py[DEBUG]: Read 1285 bytes from /tmp/tmpyDKB3M/openstack/2012-08-10/meta_data.json
2016-01-28 15:47:14,393 - util.py[DEBUG]: Reading from /tmp/tmpyDKB3M/ec2/latest/meta-data.json (quiet=False)
2016-01-28 15:47:14,393 - util.py[DEBUG]: Read 1055 bytes from /tmp/tmpyDKB3M/ec2/latest/meta-data.json
2016-01-28 15:47:14,393 - util.py[DEBUG]: Running command ['umount', '-l', '/tmp/tmpyDKB3M'] with allowed return codes [0] (shell=False, capture=True)
2016-01-28 15:47:14,399 - util.py[DEBUG]: Recursively deleting /tmp/tmpyDKB3M
2016-01-28 15:47:14,399 - importer.py[DEBUG]: Looking for modules ['cloudinit.mergers.m_list'] that have attributes ['Merger']
2016-01-28 15:47:14,399 - importer.py[DEBUG]: Found m_list with attributes ['Merger'] in ['cloudinit.mergers.m_list']
2016-01-28 15:47:14,399 - importer.py[DEBUG]: Looking for modules ['cloudinit.mergers.m_dict'] that have attributes ['Merger']
2016-01-28 15:47:14,400 - importer.py[DEBUG]: Found m_dict with attributes ['Merger'] in ['cloudinit.mergers.m_dict']
2016-01-28 15:47:14,400 - importer.py[DEBUG]: Looking for modules ['cloudinit.mergers.m_str'] that have attributes ['Merger']
2016-01-28 15:47:14,400 - importer.py[DEBUG]: Found m_str with attributes ['Merger'] in ['cloudinit.mergers.m_str']
2016-01-28 15:47:14,400 - __init__.py[DEBUG]: Merging 'dict' into 'dict' using method '_handle_unknown' of 'LookupMerger: (3)'
2016-01-28 15:47:14,400 - __init__.py[DEBUG]: Merging using located merger 'DictMerger: (method=no_replace,recurse_str=False,recurse_dict=True,recurse_array=False,allow_delete=False)' since it had method '_on_dict'
2016-01-28 15:47:14,400 - importer.py[DEBUG]: Looking for modules ['cloudinit.mergers.m_list'] that have attributes ['Merger']
2016-01-28 15:47:14,400 - importer.py[DEBUG]: Found m_list with attributes ['Merger'] in ['cloudinit.mergers.m_list']
2016-01-28 15:47:14,400 - importer.py[DEBUG]: Looking for modules ['cloudinit.mergers.m_dict'] that have attributes ['Merger']
2016-01-28 15:47:14,400 - importer.py[DEBUG]: Found m_dict with attributes ['Merger'] in ['cloudinit.mergers.m_dict']
2016-01-28 15:47:14,400 - importer.py[DEBUG]: Looking for modules ['cloudinit.mergers.m_str'] that have attributes ['Merger']
2016-01-28 15:47:14,400 - importer.py[DEBUG]: Found m_str with attributes ['Merger'] in ['cloudinit.mergers.m_str']
2016-01-28 15:47:14,400 - __init__.py[DEBUG]: Merging 'dict' into 'dict' using method '_handle_unknown' of 'LookupMerger: (3)'
2016-01-28 15:47:14,400 - __init__.py[DEBUG]: Merging using located merger 'DictMerger: (method=no_replace,recurse_str=False,recurse_dict=True,recurse_array=False,allow_delete=False)' since it had method '_on_dict'
2016-01-28 15:47:14,401 - util.py[DEBUG]: Reading from /var/lib/cloud/data/instance-id (quiet=False)
2016-01-28 15:47:14,401 - DataSourceConfigDrive.py[DEBUG]: DataSourceConfigDrive [local,ver=None][source=None]: not claiming datasource, dsmode=net
2016-01-28 15:47:14,401 - cloud-init[DEBUG]: No local datasource found
2016-01-28 15:47:14,401 - util.py[DEBUG]: Reading from /proc/uptime (quiet=False)
2016-01-28 15:47:14,401 - util.py[DEBUG]: Read 12 bytes from /proc/uptime
2016-01-28 15:47:14,402 - util.py[DEBUG]: cloud-init mode 'init' took 0.134 seconds (0.13)
2016-01-28 15:47:14,949 - util.py[DEBUG]: Cloud-init v. 0.7.5 running 'init' at Thu, 28 Jan 2016 15:47:14 +0000. Up 19.11 seconds.
2016-01-28 15:47:14,951 - util.py[DEBUG]: Writing to /var/log/cloud-init.log - ab: [420] 0 bytes
2016-01-28 15:47:14,951 - util.py[DEBUG]: Changing the ownership of /var/log/cloud-init.log to 101:4
2016-01-28 15:47:14,952 - util.py[DEBUG]: Running command ['ifconfig', '-a'] with allowed return codes [0] (shell=False, capture=True)
2016-01-28 15:47:14,957 - util.py[DEBUG]: Running command ['netstat', '-rn'] with allowed return codes [0] (shell=False, capture=True)
2016-01-28 15:47:14,964 - cloud-init[DEBUG]: Checking to see if files that we need already exist from a previous run that would allow us to stop early.
2016-01-28 15:47:14,964 - util.py[DEBUG]: Reading from /var/lib/cloud/data/no-net (quiet=False)
2016-01-28 15:47:14,964 - util.py[DEBUG]: Reading from /var/lib/cloud/instance/obj.pkl (quiet=False)
2016-01-28 15:47:14,964 - util.py[DEBUG]: Reading from /var/lib/cloud/instance/obj.pkl (quiet=False)
2016-01-28 15:47:14,965 - importer.py[DEBUG]: Looking for modules ['ubuntu', 'cloudinit.distros.ubuntu'] that have attributes ['Distro']
2016-01-28 15:47:14,965 - importer.py[DEBUG]: Failed at attempted import of 'ubuntu' due to: No module named ubuntu
2016-01-28 15:47:14,966 - importer.py[DEBUG]: Found ubuntu with attributes ['Distro'] in ['cloudinit.distros.ubuntu']
2016-01-28 15:47:14,966 - stages.py[DEBUG]: Using distro class <class 'cloudinit.distros.ubuntu.Distro'>
2016-01-28 15:47:14,966 - __init__.py[DEBUG]: Looking for for data source in: ['ConfigDrive', 'None'], via packages ['', 'cloudinit.sources'] that matches dependencies ['FILESYSTEM', 'NETWORK']
2016-01-28 15:47:14,967 - importer.py[DEBUG]: Looking for modules ['DataSourceConfigDrive', 'cloudinit.sources.DataSourceConfigDrive'] that have attributes ['get_datasource_list']
2016-01-28 15:47:14,967 - importer.py[DEBUG]: Failed at attempted import of 'DataSourceConfigDrive' due to: No module named DataSourceConfigDrive
2016-01-28 15:47:14,969 - importer.py[DEBUG]: Found DataSourceConfigDrive with attributes ['get_datasource_list'] in ['cloudinit.sources.DataSourceConfigDrive']
2016-01-28 15:47:14,969 - importer.py[DEBUG]: Looking for modules ['DataSourceNone', 'cloudinit.sources.DataSourceNone'] that have attributes ['get_datasource_list']
2016-01-28 15:47:14,969 - importer.py[DEBUG]: Failed at attempted import of 'DataSourceNone' due to: No module named DataSourceNone
2016-01-28 15:47:14,970 - importer.py[DEBUG]: Found DataSourceNone with attributes ['get_datasource_list'] in ['cloudinit.sources.DataSourceNone']
2016-01-28 15:47:14,970 - __init__.py[DEBUG]: Searching for data source in: ['DataSourceConfigDriveNet', 'DataSourceNone']
2016-01-28 15:47:14,970 - __init__.py[DEBUG]: Seeing if we can get any data from <class 'cloudinit.sources.DataSourceConfigDrive.DataSourceConfigDriveNet'>
2016-01-28 15:47:14,970 - util.py[DEBUG]: Running command ['blkid', '-odevice', '/dev/sr0'] with allowed return codes [0, 2] (shell=False, capture=True)
2016-01-28 15:47:14,973 - util.py[DEBUG]: Running command ['blkid', '-odevice', '/dev/sr1'] with allowed return codes [0, 2] (shell=False, capture=True)
2016-01-28 15:47:14,975 - util.py[DEBUG]: Running command ['blkid', '-tTYPE=vfat', '-odevice'] with allowed return codes [0, 2] (shell=False, capture=True)
2016-01-28 15:47:14,977 - util.py[DEBUG]: Running command ['blkid', '-tTYPE=iso9660', '-odevice'] with allowed return codes [0, 2] (shell=False, capture=True)
2016-01-28 15:47:14,979 - util.py[DEBUG]: Running command ['blkid', '-tLABEL=config-2', '-odevice'] with allowed return codes [0, 2] (shell=False, capture=True)
2016-01-28 15:47:14,981 - util.py[DEBUG]: Reading from /proc/mounts (quiet=False)
2016-01-28 15:47:14,981 - util.py[DEBUG]: Read 915 bytes from /proc/mounts
2016-01-28 15:47:14,982 - util.py[DEBUG]: Fetched {'none': {'mountpoint': '/proc/xen', 'opts': 'rw,relatime', 'fstype': 'xenfs'}, 'devpts': {'mountpoint': '/dev/pts', 'opts': 'rw,nosuid,noexec,relatime,gid=5,mode=620,ptmxmode=000', 'fstype': 'devpts'}, 'sysfs': {'mountpoint': '/sys', 'opts': 'rw,nosuid,nodev,noexec,relatime', 'fstype': 'sysfs'}, 'udev': {'mountpoint': '/dev', 'opts': 'rw,relatime,size=495240k,nr_inodes=123810,mode=755', 'fstype': 'devtmpfs'}, '/dev/xvda1': {'mountpoint': '/', 'opts': 'rw,noatime,nobarrier,errors=remount-ro,data=ordered', 'fstype': 'ext4'}, 'tmpfs': {'mountpoint': '/run', 'opts': 'rw,nosuid,noexec,relatime,size=101224k,mode=755', 'fstype': 'tmpfs'}, 'proc': {'mountpoint': '/proc', 'opts': 'rw,nosuid,nodev,noexec,relatime', 'fstype': 'proc'}, 'rootfs': {'mountpoint': '/', 'opts': 'rw', 'fstype': 'rootfs'}} mounts from proc
2016-01-28 15:47:14,982 - util.py[DEBUG]: Running command ['mount', '-o', 'ro,sync', '/dev/xvdd', '/tmp/tmpKb2FTb'] with allowed return codes [0] (shell=False, capture=True)
2016-01-28 15:47:15,016 - util.py[DEBUG]: Reading from /tmp/tmpKb2FTb/openstack/2012-08-10/user_data (quiet=False)
2016-01-28 15:47:15,016 - util.py[DEBUG]: Read 3923 bytes from /tmp/tmpKb2FTb/openstack/2012-08-10/user_data
2016-01-28 15:47:15,016 - util.py[DEBUG]: Reading from /tmp/tmpKb2FTb/openstack/2012-08-10/meta_data.json (quiet=False)
2016-01-28 15:47:15,017 - util.py[DEBUG]: Read 1285 bytes from /tmp/tmpKb2FTb/openstack/2012-08-10/meta_data.json
2016-01-28 15:47:15,018 - util.py[DEBUG]: Reading from /tmp/tmpKb2FTb/ec2/latest/meta-data.json (quiet=False)
2016-01-28 15:47:15,018 - util.py[DEBUG]: Read 1055 bytes from /tmp/tmpKb2FTb/ec2/latest/meta-data.json
2016-01-28 15:47:15,018 - util.py[DEBUG]: Running command ['umount', '-l', '/tmp/tmpKb2FTb'] with allowed return codes [0] (shell=False, capture=True)
2016-01-28 15:47:15,022 - util.py[DEBUG]: Recursively deleting /tmp/tmpKb2FTb
2016-01-28 15:47:15,022 - importer.py[DEBUG]: Looking for modules ['cloudinit.mergers.m_list'] that have attributes ['Merger']
2016-01-28 15:47:15,022 - importer.py[DEBUG]: Found m_list with attributes ['Merger'] in ['cloudinit.mergers.m_list']
2016-01-28 15:47:15,022 - importer.py[DEBUG]: Looking for modules ['cloudinit.mergers.m_dict'] that have attributes ['Merger']
2016-01-28 15:47:15,023 - importer.py[DEBUG]: Found m_dict with attributes ['Merger'] in ['cloudinit.mergers.m_dict']
2016-01-28 15:47:15,023 - importer.py[DEBUG]: Looking for modules ['cloudinit.mergers.m_str'] that have attributes ['Merger']
2016-01-28 15:47:15,023 - importer.py[DEBUG]: Found m_str with attributes ['Merger'] in ['cloudinit.mergers.m_str']
2016-01-28 15:47:15,023 - __init__.py[DEBUG]: Merging 'dict' into 'dict' using method '_handle_unknown' of 'LookupMerger: (3)'
2016-01-28 15:47:15,023 - __init__.py[DEBUG]: Merging using located merger 'DictMerger: (method=no_replace,recurse_str=False,recurse_dict=True,recurse_array=False,allow_delete=False)' since it had method '_on_dict'
2016-01-28 15:47:15,023 - importer.py[DEBUG]: Looking for modules ['cloudinit.mergers.m_list'] that have attributes ['Merger']
2016-01-28 15:47:15,023 - importer.py[DEBUG]: Found m_list with attributes ['Merger'] in ['cloudinit.mergers.m_list']
2016-01-28 15:47:15,023 - importer.py[DEBUG]: Looking for modules ['cloudinit.mergers.m_dict'] that have attributes ['Merger']
2016-01-28 15:47:15,023 - importer.py[DEBUG]: Found m_dict with attributes ['Merger'] in ['cloudinit.mergers.m_dict']
2016-01-28 15:47:15,023 - importer.py[DEBUG]: Looking for modules ['cloudinit.mergers.m_str'] that have attributes ['Merger']
2016-01-28 15:47:15,023 - importer.py[DEBUG]: Found m_str with attributes ['Merger'] in ['cloudinit.mergers.m_str']
2016-01-28 15:47:15,024 - __init__.py[DEBUG]: Merging 'dict' into 'dict' using method '_handle_unknown' of 'LookupMerger: (3)'
2016-01-28 15:47:15,024 - __init__.py[DEBUG]: Merging using located merger 'DictMerger: (method=no_replace,recurse_str=False,recurse_dict=True,recurse_array=False,allow_delete=False)' since it had method '_on_dict'
2016-01-28 15:47:15,024 - util.py[DEBUG]: Reading from /var/lib/cloud/data/instance-id (quiet=False)
2016-01-28 15:47:15,024 - stages.py[INFO]: Loaded datasource DataSourceConfigDriveNet - DataSourceConfigDriveNet [net,ver=2][source=/dev/xvdd]
2016-01-28 15:47:15,024 - util.py[DEBUG]: Reading from /proc/cmdline (quiet=False)
2016-01-28 15:47:15,024 - util.py[DEBUG]: Read 123 bytes from /proc/cmdline
2016-01-28 15:47:15,024 - util.py[DEBUG]: Reading from /etc/cloud/cloud.cfg (quiet=False)
2016-01-28 15:47:15,024 - util.py[DEBUG]: Read 2960 bytes from /etc/cloud/cloud.cfg
2016-01-28 15:47:15,024 - util.py[DEBUG]: Attempting to load yaml from string of length 2960 with allowed root types (<type 'dict'>,)
2016-01-28 15:47:15,038 - util.py[DEBUG]: Reading from /etc/cloud/cloud.cfg.d/90_dpkg.cfg (quiet=False)
2016-01-28 15:47:15,039 - util.py[DEBUG]: Read 94 bytes from /etc/cloud/cloud.cfg.d/90_dpkg.cfg
2016-01-28 15:47:15,039 - util.py[DEBUG]: Attempting to load yaml from string of length 94 with allowed root types (<type 'dict'>,)
2016-01-28 15:47:15,039 - util.py[DEBUG]: Reading from /etc/cloud/cloud.cfg.d/10_rackspace.cfg (quiet=False)
2016-01-28 15:47:15,039 - util.py[DEBUG]: Read 114 bytes from /etc/cloud/cloud.cfg.d/10_rackspace.cfg
2016-01-28 15:47:15,040 - util.py[DEBUG]: Attempting to load yaml from string of length 114 with allowed root types (<type 'dict'>,)
2016-01-28 15:47:15,041 - util.py[DEBUG]: Reading from /etc/cloud/cloud.cfg.d/05_logging.cfg (quiet=False)
2016-01-28 15:47:15,041 - util.py[DEBUG]: Read 1910 bytes from /etc/cloud/cloud.cfg.d/05_logging.cfg
2016-01-28 15:47:15,041 - util.py[DEBUG]: Attempting to load yaml from string of length 1910 with allowed root types (<type 'dict'>,)
2016-01-28 15:47:15,045 - importer.py[DEBUG]: Looking for modules ['cloudinit.mergers.m_list'] that have attributes ['Merger']
2016-01-28 15:47:15,045 - importer.py[DEBUG]: Found m_list with attributes ['Merger'] in ['cloudinit.mergers.m_list']
2016-01-28 15:47:15,045 - importer.py[DEBUG]: Looking for modules ['cloudinit.mergers.m_dict'] that have attributes ['Merger']
2016-01-28 15:47:15,045 - importer.py[DEBUG]: Found m_dict with attributes ['Merger'] in ['cloudinit.mergers.m_dict']
2016-01-28 15:47:15,045 - importer.py[DEBUG]: Looking for modules ['cloudinit.mergers.m_str'] that have attributes ['Merger']
2016-01-28 15:47:15,045 - importer.py[DEBUG]: Found m_str with attributes ['Merger'] in ['cloudinit.mergers.m_str']
2016-01-28 15:47:15,045 - __init__.py[DEBUG]: Merging 'dict' into 'dict' using method '_handle_unknown' of 'LookupMerger: (3)'
2016-01-28 15:47:15,045 - __init__.py[DEBUG]: Merging using located merger 'DictMerger: (method=no_replace,recurse_str=False,recurse_dict=True,recurse_array=False,allow_delete=False)' since it had method '_on_dict'
2016-01-28 15:47:15,046 - importer.py[DEBUG]: Looking for modules ['cloudinit.mergers.m_list'] that have attributes ['Merger']
2016-01-28 15:47:15,046 - importer.py[DEBUG]: Found m_list with attributes ['Merger'] in ['cloudinit.mergers.m_list']
2016-01-28 15:47:15,046 - importer.py[DEBUG]: Looking for modules ['cloudinit.mergers.m_dict'] that have attributes ['Merger']
2016-01-28 15:47:15,046 - importer.py[DEBUG]: Found m_dict with attributes ['Merger'] in ['cloudinit.mergers.m_dict']
2016-01-28 15:47:15,046 - importer.py[DEBUG]: Looking for modules ['cloudinit.mergers.m_str'] that have attributes ['Merger']
2016-01-28 15:47:15,046 - importer.py[DEBUG]: Found m_str with attributes ['Merger'] in ['cloudinit.mergers.m_str']
2016-01-28 15:47:15,046 - __init__.py[DEBUG]: Merging 'dict' into 'dict' using method '_handle_unknown' of 'LookupMerger: (3)'
2016-01-28 15:47:15,046 - __init__.py[DEBUG]: Merging using located merger 'DictMerger: (method=no_replace,recurse_str=False,recurse_dict=True,recurse_array=False,allow_delete=False)' since it had method '_on_dict'
2016-01-28 15:47:15,046 - importer.py[DEBUG]: Looking for modules ['cloudinit.mergers.m_list'] that have attributes ['Merger']
2016-01-28 15:47:15,046 - importer.py[DEBUG]: Found m_list with attributes ['Merger'] in ['cloudinit.mergers.m_list']
2016-01-28 15:47:15,046 - importer.py[DEBUG]: Looking for modules ['cloudinit.mergers.m_dict'] that have attributes ['Merger']
2016-01-28 15:47:15,046 - importer.py[DEBUG]: Found m_dict with attributes ['Merger'] in ['cloudinit.mergers.m_dict']
2016-01-28 15:47:15,046 - importer.py[DEBUG]: Looking for modules ['cloudinit.mergers.m_str'] that have attributes ['Merger']
2016-01-28 15:47:15,046 - importer.py[DEBUG]: Found m_str with attributes ['Merger'] in ['cloudinit.mergers.m_str']
2016-01-28 15:47:15,047 - __init__.py[DEBUG]: Merging 'dict' into 'dict' using method '_handle_unknown' of 'LookupMerger: (3)'
2016-01-28 15:47:15,047 - __init__.py[DEBUG]: Merging using located merger 'DictMerger: (method=no_replace,recurse_str=False,recurse_dict=True,recurse_array=False,allow_delete=False)' since it had method '_on_dict'
2016-01-28 15:47:15,047 - importer.py[DEBUG]: Looking for modules ['cloudinit.mergers.m_list'] that have attributes ['Merger']
2016-01-28 15:47:15,047 - importer.py[DEBUG]: Found m_list with attributes ['Merger'] in ['cloudinit.mergers.m_list']
2016-01-28 15:47:15,047 - importer.py[DEBUG]: Looking for modules ['cloudinit.mergers.m_dict'] that have attributes ['Merger']
2016-01-28 15:47:15,047 - importer.py[DEBUG]: Found m_dict with attributes ['Merger'] in ['cloudinit.mergers.m_dict']
2016-01-28 15:47:15,047 - importer.py[DEBUG]: Looking for modules ['cloudinit.mergers.m_str'] that have attributes ['Merger']
2016-01-28 15:47:15,047 - importer.py[DEBUG]: Found m_str with attributes ['Merger'] in ['cloudinit.mergers.m_str']
2016-01-28 15:47:15,047 - __init__.py[DEBUG]: Merging 'dict' into 'dict' using method '_handle_unknown' of 'LookupMerger: (3)'
2016-01-28 15:47:15,047 - __init__.py[DEBUG]: Merging using located merger 'DictMerger: (method=no_replace,recurse_str=False,recurse_dict=True,recurse_array=False,allow_delete=False)' since it had method '_on_dict'
2016-01-28 15:47:15,047 - importer.py[DEBUG]: Looking for modules ['cloudinit.mergers.m_list'] that have attributes ['Merger']
2016-01-28 15:47:15,047 - importer.py[DEBUG]: Found m_list with attributes ['Merger'] in ['cloudinit.mergers.m_list']
2016-01-28 15:47:15,047 - importer.py[DEBUG]: Looking for modules ['cloudinit.mergers.m_dict'] that have attributes ['Merger']
2016-01-28 15:47:15,047 - importer.py[DEBUG]: Found m_dict with attributes ['Merger'] in ['cloudinit.mergers.m_dict']
2016-01-28 15:47:15,048 - importer.py[DEBUG]: Looking for modules ['cloudinit.mergers.m_str'] that have attributes ['Merger']
2016-01-28 15:47:15,048 - importer.py[DEBUG]: Found m_str with attributes ['Merger'] in ['cloudinit.mergers.m_str']
2016-01-28 15:47:15,048 - __init__.py[DEBUG]: Merging 'dict' into 'dict' using method '_handle_unknown' of 'LookupMerger: (3)'
2016-01-28 15:47:15,048 - __init__.py[DEBUG]: Merging using located merger 'DictMerger: (method=no_replace,recurse_str=False,recurse_dict=True,recurse_array=False,allow_delete=False)' since it had method '_on_dict'
2016-01-28 15:47:15,048 - importer.py[DEBUG]: Looking for modules ['cloudinit.mergers.m_list'] that have attributes ['Merger']
2016-01-28 15:47:15,048 - importer.py[DEBUG]: Found m_list with attributes ['Merger'] in ['cloudinit.mergers.m_list']
2016-01-28 15:47:15,048 - importer.py[DEBUG]: Looking for modules ['cloudinit.mergers.m_dict'] that have attributes ['Merger']
2016-01-28 15:47:15,048 - importer.py[DEBUG]: Found m_dict with attributes ['Merger'] in ['cloudinit.mergers.m_dict']
2016-01-28 15:47:15,048 - importer.py[DEBUG]: Looking for modules ['cloudinit.mergers.m_str'] that have attributes ['Merger']
2016-01-28 15:47:15,048 - importer.py[DEBUG]: Found m_str with attributes ['Merger'] in ['cloudinit.mergers.m_str']
2016-01-28 15:47:15,048 - __init__.py[DEBUG]: Merging 'dict' into 'dict' using method '_handle_unknown' of 'LookupMerger: (3)'
2016-01-28 15:47:15,048 - __init__.py[DEBUG]: Merging using located merger 'DictMerger: (method=no_replace,recurse_str=False,recurse_dict=True,recurse_array=False,allow_delete=False)' since it had method '_on_dict'
2016-01-28 15:47:15,048 - importer.py[DEBUG]: Looking for modules ['cloudinit.mergers.m_list'] that have attributes ['Merger']
2016-01-28 15:47:15,049 - importer.py[DEBUG]: Found m_list with attributes ['Merger'] in ['cloudinit.mergers.m_list']
2016-01-28 15:47:15,049 - importer.py[DEBUG]: Looking for modules ['cloudinit.mergers.m_dict'] that have attributes ['Merger']
2016-01-28 15:47:15,049 - importer.py[DEBUG]: Found m_dict with attributes ['Merger'] in ['cloudinit.mergers.m_dict']
2016-01-28 15:47:15,049 - importer.py[DEBUG]: Looking for modules ['cloudinit.mergers.m_str'] that have attributes ['Merger']
2016-01-28 15:47:15,049 - importer.py[DEBUG]: Found m_str with attributes ['Merger'] in ['cloudinit.mergers.m_str']
2016-01-28 15:47:15,049 - __init__.py[DEBUG]: Merging 'dict' into 'dict' using method '_handle_unknown' of 'LookupMerger: (3)'
2016-01-28 15:47:15,049 - __init__.py[DEBUG]: Merging using located merger 'DictMerger: (method=no_replace,recurse_str=False,recurse_dict=True,recurse_array=False,allow_delete=False)' since it had method '_on_dict'
2016-01-28 15:47:15,049 - __init__.py[DEBUG]: Merging 'dict' into 'dict' using method '_handle_unknown' of 'LookupMerger: (3)'
2016-01-28 15:47:15,049 - __init__.py[DEBUG]: Merging using located merger 'DictMerger: (method=no_replace,recurse_str=False,recurse_dict=True,recurse_array=False,allow_delete=False)' since it had method '_on_dict'
2016-01-28 15:47:15,049 - __init__.py[DEBUG]: Merging 'dict' into 'dict' using method '_handle_unknown' of 'LookupMerger: (3)'
2016-01-28 15:47:15,049 - __init__.py[DEBUG]: Merging using located merger 'DictMerger: (method=no_replace,recurse_str=False,recurse_dict=True,recurse_array=False,allow_delete=False)' since it had method '_on_dict'
2016-01-28 15:47:15,049 - importer.py[DEBUG]: Looking for modules ['cloudinit.mergers.m_list'] that have attributes ['Merger']
2016-01-28 15:47:15,049 - importer.py[DEBUG]: Found m_list with attributes ['Merger'] in ['cloudinit.mergers.m_list']
2016-01-28 15:47:15,050 - importer.py[DEBUG]: Looking for modules ['cloudinit.mergers.m_dict'] that have attributes ['Merger']
2016-01-28 15:47:15,050 - importer.py[DEBUG]: Found m_dict with attributes ['Merger'] in ['cloudinit.mergers.m_dict']
2016-01-28 15:47:15,050 - importer.py[DEBUG]: Looking for modules ['cloudinit.mergers.m_str'] that have attributes ['Merger']
2016-01-28 15:47:15,050 - importer.py[DEBUG]: Found m_str with attributes ['Merger'] in ['cloudinit.mergers.m_str']
2016-01-28 15:47:15,050 - __init__.py[DEBUG]: Merging 'dict' into 'dict' using method '_handle_unknown' of 'LookupMerger: (3)'
2016-01-28 15:47:15,050 - __init__.py[DEBUG]: Merging using located merger 'DictMerger: (method=no_replace,recurse_str=False,recurse_dict=True,recurse_array=False,allow_delete=False)' since it had method '_on_dict'
2016-01-28 15:47:15,050 - util.py[DEBUG]: Attempting to remove /var/lib/cloud/instance
2016-01-28 15:47:15,050 - util.py[DEBUG]: Creating symbolic link from '/var/lib/cloud/instance' => '/var/lib/cloud/instances/13862411-b73a-4aa1-9735-9ad34e302b41'
2016-01-28 15:47:15,051 - util.py[DEBUG]: Reading from /var/lib/cloud/instances/13862411-b73a-4aa1-9735-9ad34e302b41/datasource (quiet=False)
2016-01-28 15:47:15,051 - util.py[DEBUG]: Writing to /var/lib/cloud/instances/13862411-b73a-4aa1-9735-9ad34e302b41/datasource - wb: [420] 81 bytes
2016-01-28 15:47:15,052 - util.py[DEBUG]: Writing to /var/lib/cloud/data/previous-datasource - wb: [420] 81 bytes
2016-01-28 15:47:15,052 - util.py[DEBUG]: Reading from /var/lib/cloud/data/instance-id (quiet=False)
2016-01-28 15:47:15,052 - util.py[DEBUG]: Writing to /var/lib/cloud/data/instance-id - wb: [420] 37 bytes
2016-01-28 15:47:15,052 - util.py[DEBUG]: Writing to /var/lib/cloud/data/previous-instance-id - wb: [420] 37 bytes
2016-01-28 15:47:15,052 - cloud-init[DEBUG]: init will now be targeting instance id: 13862411-b73a-4aa1-9735-9ad34e302b41
2016-01-28 15:47:15,053 - util.py[DEBUG]: Reading from /proc/cmdline (quiet=False)
2016-01-28 15:47:15,053 - util.py[DEBUG]: Read 123 bytes from /proc/cmdline
2016-01-28 15:47:15,053 - util.py[DEBUG]: Reading from /etc/cloud/cloud.cfg (quiet=False)
2016-01-28 15:47:15,053 - util.py[DEBUG]: Read 2960 bytes from /etc/cloud/cloud.cfg
2016-01-28 15:47:15,053 - util.py[DEBUG]: Attempting to load yaml from string of length 2960 with allowed root types (<type 'dict'>,)
2016-01-28 15:47:15,066 - util.py[DEBUG]: Reading from /etc/cloud/cloud.cfg.d/90_dpkg.cfg (quiet=False)
2016-01-28 15:47:15,066 - util.py[DEBUG]: Read 94 bytes from /etc/cloud/cloud.cfg.d/90_dpkg.cfg
2016-01-28 15:47:15,066 - util.py[DEBUG]: Attempting to load yaml from string of length 94 with allowed root types (<type 'dict'>,)
2016-01-28 15:47:15,067 - util.py[DEBUG]: Reading from /etc/cloud/cloud.cfg.d/10_rackspace.cfg (quiet=False)
2016-01-28 15:47:15,067 - util.py[DEBUG]: Read 114 bytes from /etc/cloud/cloud.cfg.d/10_rackspace.cfg
2016-01-28 15:47:15,067 - util.py[DEBUG]: Attempting to load yaml from string of length 114 with allowed root types (<type 'dict'>,)
2016-01-28 15:47:15,068 - util.py[DEBUG]: Reading from /etc/cloud/cloud.cfg.d/05_logging.cfg (quiet=False)
2016-01-28 15:47:15,068 - util.py[DEBUG]: Read 1910 bytes from /etc/cloud/cloud.cfg.d/05_logging.cfg
2016-01-28 15:47:15,068 - util.py[DEBUG]: Attempting to load yaml from string of length 1910 with allowed root types (<type 'dict'>,)
2016-01-28 15:47:15,072 - importer.py[DEBUG]: Looking for modules ['cloudinit.mergers.m_list'] that have attributes ['Merger']
2016-01-28 15:47:15,072 - importer.py[DEBUG]: Found m_list with attributes ['Merger'] in ['cloudinit.mergers.m_list']
2016-01-28 15:47:15,072 - importer.py[DEBUG]: Looking for modules ['cloudinit.mergers.m_dict'] that have attributes ['Merger']
2016-01-28 15:47:15,073 - importer.py[DEBUG]: Found m_dict with attributes ['Merger'] in ['cloudinit.mergers.m_dict']
2016-01-28 15:47:15,073 - importer.py[DEBUG]: Looking for modules ['cloudinit.mergers.m_str'] that have attributes ['Merger']
2016-01-28 15:47:15,073 - importer.py[DEBUG]: Found m_str with attributes ['Merger'] in ['cloudinit.mergers.m_str']
2016-01-28 15:47:15,073 - __init__.py[DEBUG]: Merging 'dict' into 'dict' using method '_handle_unknown' of 'LookupMerger: (3)'
2016-01-28 15:47:15,073 - __init__.py[DEBUG]: Merging using located merger 'DictMerger: (method=no_replace,recurse_str=False,recurse_dict=True,recurse_array=False,allow_delete=False)' since it had method '_on_dict'
2016-01-28 15:47:15,073 - importer.py[DEBUG]: Looking for modules ['cloudinit.mergers.m_list'] that have attributes ['Merger']
2016-01-28 15:47:15,073 - importer.py[DEBUG]: Found m_list with attributes ['Merger'] in ['cloudinit.mergers.m_list']
2016-01-28 15:47:15,073 - importer.py[DEBUG]: Looking for modules ['cloudinit.mergers.m_dict'] that have attributes ['Merger']
2016-01-28 15:47:15,073 - importer.py[DEBUG]: Found m_dict with attributes ['Merger'] in ['cloudinit.mergers.m_dict']
2016-01-28 15:47:15,073 - importer.py[DEBUG]: Looking for modules ['cloudinit.mergers.m_str'] that have attributes ['Merger']
2016-01-28 15:47:15,073 - importer.py[DEBUG]: Found m_str with attributes ['Merger'] in ['cloudinit.mergers.m_str']
2016-01-28 15:47:15,073 - __init__.py[DEBUG]: Merging 'dict' into 'dict' using method '_handle_unknown' of 'LookupMerger: (3)'
2016-01-28 15:47:15,073 - __init__.py[DEBUG]: Merging using located merger 'DictMerger: (method=no_replace,recurse_str=False,recurse_dict=True,recurse_array=False,allow_delete=False)' since it had method '_on_dict'
2016-01-28 15:47:15,073 - importer.py[DEBUG]: Looking for modules ['cloudinit.mergers.m_list'] that have attributes ['Merger']
2016-01-28 15:47:15,074 - importer.py[DEBUG]: Found m_list with attributes ['Merger'] in ['cloudinit.mergers.m_list']
2016-01-28 15:47:15,074 - importer.py[DEBUG]: Looking for modules ['cloudinit.mergers.m_dict'] that have attributes ['Merger']
2016-01-28 15:47:15,074 - importer.py[DEBUG]: Found m_dict with attributes ['Merger'] in ['cloudinit.mergers.m_dict']
2016-01-28 15:47:15,074 - importer.py[DEBUG]: Looking for modules ['cloudinit.mergers.m_str'] that have attributes ['Merger']
2016-01-28 15:47:15,074 - importer.py[DEBUG]: Found m_str with attributes ['Merger'] in ['cloudinit.mergers.m_str']
2016-01-28 15:47:15,074 - __init__.py[DEBUG]: Merging 'dict' into 'dict' using method '_handle_unknown' of 'LookupMerger: (3)'
2016-01-28 15:47:15,074 - __init__.py[DEBUG]: Merging using located merger 'DictMerger: (method=no_replace,recurse_str=False,recurse_dict=True,recurse_array=False,allow_delete=False)' since it had method '_on_dict'
2016-01-28 15:47:15,074 - importer.py[DEBUG]: Looking for modules ['cloudinit.mergers.m_list'] that have attributes ['Merger']
2016-01-28 15:47:15,074 - importer.py[DEBUG]: Found m_list with attributes ['Merger'] in ['cloudinit.mergers.m_list']
2016-01-28 15:47:15,074 - importer.py[DEBUG]: Looking for modules ['cloudinit.mergers.m_dict'] that have attributes ['Merger']
2016-01-28 15:47:15,074 - importer.py[DEBUG]: Found m_dict with attributes ['Merger'] in ['cloudinit.mergers.m_dict']
2016-01-28 15:47:15,074 - importer.py[DEBUG]: Looking for modules ['cloudinit.mergers.m_str'] that have attributes ['Merger']
2016-01-28 15:47:15,074 - importer.py[DEBUG]: Found m_str with attributes ['Merger'] in ['cloudinit.mergers.m_str']
2016-01-28 15:47:15,074 - __init__.py[DEBUG]: Merging 'dict' into 'dict' using method '_handle_unknown' of 'LookupMerger: (3)'
2016-01-28 15:47:15,075 - __init__.py[DEBUG]: Merging using located merger 'DictMerger: (method=no_replace,recurse_str=False,recurse_dict=True,recurse_array=False,allow_delete=False)' since it had method '_on_dict'
2016-01-28 15:47:15,075 - importer.py[DEBUG]: Looking for modules ['cloudinit.mergers.m_list'] that have attributes ['Merger']
2016-01-28 15:47:15,075 - importer.py[DEBUG]: Found m_list with attributes ['Merger'] in ['cloudinit.mergers.m_list']
2016-01-28 15:47:15,075 - importer.py[DEBUG]: Looking for modules ['cloudinit.mergers.m_dict'] that have attributes ['Merger']
2016-01-28 15:47:15,075 - importer.py[DEBUG]: Found m_dict with attributes ['Merger'] in ['cloudinit.mergers.m_dict']
2016-01-28 15:47:15,075 - importer.py[DEBUG]: Looking for modules ['cloudinit.mergers.m_str'] that have attributes ['Merger']
2016-01-28 15:47:15,075 - importer.py[DEBUG]: Found m_str with attributes ['Merger'] in ['cloudinit.mergers.m_str']
2016-01-28 15:47:15,075 - __init__.py[DEBUG]: Merging 'dict' into 'dict' using method '_handle_unknown' of 'LookupMerger: (3)'
2016-01-28 15:47:15,075 - __init__.py[DEBUG]: Merging using located merger 'DictMerger: (method=no_replace,recurse_str=False,recurse_dict=True,recurse_array=False,allow_delete=False)' since it had method '_on_dict'
2016-01-28 15:47:15,075 - importer.py[DEBUG]: Looking for modules ['cloudinit.mergers.m_list'] that have attributes ['Merger']
2016-01-28 15:47:15,075 - importer.py[DEBUG]: Found m_list with attributes ['Merger'] in ['cloudinit.mergers.m_list']
2016-01-28 15:47:15,075 - importer.py[DEBUG]: Looking for modules ['cloudinit.mergers.m_dict'] that have attributes ['Merger']
2016-01-28 15:47:15,075 - importer.py[DEBUG]: Found m_dict with attributes ['Merger'] in ['cloudinit.mergers.m_dict']
2016-01-28 15:47:15,075 - importer.py[DEBUG]: Looking for modules ['cloudinit.mergers.m_str'] that have attributes ['Merger']
2016-01-28 15:47:15,076 - importer.py[DEBUG]: Found m_str with attributes ['Merger'] in ['cloudinit.mergers.m_str']
2016-01-28 15:47:15,076 - __init__.py[DEBUG]: Merging 'dict' into 'dict' using method '_handle_unknown' of 'LookupMerger: (3)'
2016-01-28 15:47:15,076 - __init__.py[DEBUG]: Merging using located merger 'DictMerger: (method=no_replace,recurse_str=False,recurse_dict=True,recurse_array=False,allow_delete=False)' since it had method '_on_dict'
2016-01-28 15:47:15,076 - importer.py[DEBUG]: Looking for modules ['cloudinit.mergers.m_list'] that have attributes ['Merger']
2016-01-28 15:47:15,076 - importer.py[DEBUG]: Found m_list with attributes ['Merger'] in ['cloudinit.mergers.m_list']
2016-01-28 15:47:15,076 - importer.py[DEBUG]: Looking for modules ['cloudinit.mergers.m_dict'] that have attributes ['Merger']
2016-01-28 15:47:15,076 - importer.py[DEBUG]: Found m_dict with attributes ['Merger'] in ['cloudinit.mergers.m_dict']
2016-01-28 15:47:15,076 - importer.py[DEBUG]: Looking for modules ['cloudinit.mergers.m_str'] that have attributes ['Merger']
2016-01-28 15:47:15,076 - importer.py[DEBUG]: Found m_str with attributes ['Merger'] in ['cloudinit.mergers.m_str']
2016-01-28 15:47:15,076 - __init__.py[DEBUG]: Merging 'dict' into 'dict' using method '_handle_unknown' of 'LookupMerger: (3)'
2016-01-28 15:47:15,076 - __init__.py[DEBUG]: Merging using located merger 'DictMerger: (method=no_replace,recurse_str=False,recurse_dict=True,recurse_array=False,allow_delete=False)' since it had method '_on_dict'
2016-01-28 15:47:15,076 - __init__.py[DEBUG]: Merging 'dict' into 'dict' using method '_handle_unknown' of 'LookupMerger: (3)'
2016-01-28 15:47:15,076 - __init__.py[DEBUG]: Merging using located merger 'DictMerger: (method=no_replace,recurse_str=False,recurse_dict=True,recurse_array=False,allow_delete=False)' since it had method '_on_dict'
2016-01-28 15:47:15,076 - __init__.py[DEBUG]: Merging 'dict' into 'dict' using method '_handle_unknown' of 'LookupMerger: (3)'
2016-01-28 15:47:15,077 - __init__.py[DEBUG]: Merging using located merger 'DictMerger: (method=no_replace,recurse_str=False,recurse_dict=True,recurse_array=False,allow_delete=False)' since it had method '_on_dict'
2016-01-28 15:47:15,077 - importer.py[DEBUG]: Looking for modules ['cloudinit.mergers.m_list'] that have attributes ['Merger']
2016-01-28 15:47:15,077 - importer.py[DEBUG]: Found m_list with attributes ['Merger'] in ['cloudinit.mergers.m_list']
2016-01-28 15:47:15,077 - importer.py[DEBUG]: Looking for modules ['cloudinit.mergers.m_dict'] that have attributes ['Merger']
2016-01-28 15:47:15,077 - importer.py[DEBUG]: Found m_dict with attributes ['Merger'] in ['cloudinit.mergers.m_dict']
2016-01-28 15:47:15,077 - importer.py[DEBUG]: Looking for modules ['cloudinit.mergers.m_str'] that have attributes ['Merger']
2016-01-28 15:47:15,077 - importer.py[DEBUG]: Found m_str with attributes ['Merger'] in ['cloudinit.mergers.m_str']
2016-01-28 15:47:15,077 - __init__.py[DEBUG]: Merging 'dict' into 'dict' using method '_handle_unknown' of 'LookupMerger: (3)'
2016-01-28 15:47:15,077 - __init__.py[DEBUG]: Merging using located merger 'DictMerger: (method=no_replace,recurse_str=False,recurse_dict=True,recurse_array=False,allow_delete=False)' since it had method '_on_dict'
2016-01-28 15:47:15,078 - util.py[DEBUG]: Writing to /var/lib/cloud/instance/obj.pkl - wb: [256] 12232 bytes
2016-01-28 15:47:15,078 - util.py[DEBUG]: Writing to /var/lib/cloud/instances/13862411-b73a-4aa1-9735-9ad34e302b41/user-data.txt - wb: [384] 3923 bytes
2016-01-28 15:47:15,082 - util.py[DEBUG]: Attempting to load yaml from string of length 153 with allowed root types (<type 'dict'>,)
2016-01-28 15:47:15,087 - util.py[DEBUG]: Writing to /var/lib/cloud/instances/13862411-b73a-4aa1-9735-9ad34e302b41/user-data.txt.i - wb: [384] 3983 bytes
2016-01-28 15:47:15,087 - util.py[DEBUG]: Writing to /var/lib/cloud/instances/13862411-b73a-4aa1-9735-9ad34e302b41/vendor-data.txt - wb: [384] 4 bytes
2016-01-28 15:47:15,088 - util.py[DEBUG]: Writing to /var/lib/cloud/instances/13862411-b73a-4aa1-9735-9ad34e302b41/vendor-data.txt.i - wb: [384] 345 bytes
2016-01-28 15:47:15,089 - importer.py[DEBUG]: Looking for modules ['ubuntu', 'cloudinit.distros.ubuntu'] that have attributes ['Distro']
2016-01-28 15:47:15,089 - importer.py[DEBUG]: Failed at attempted import of 'ubuntu' due to: No module named ubuntu
2016-01-28 15:47:15,089 - importer.py[DEBUG]: Found ubuntu with attributes ['Distro'] in ['cloudinit.distros.ubuntu']
2016-01-28 15:47:15,089 - stages.py[DEBUG]: Using distro class <class 'cloudinit.distros.ubuntu.Distro'>
2016-01-28 15:47:15,090 - util.py[DEBUG]: Writing to /var/lib/cloud/instances/13862411-b73a-4aa1-9735-9ad34e302b41/sem/consume_data - wb: [420] 20 bytes
2016-01-28 15:47:15,090 - helpers.py[DEBUG]: Running consume_data using lock (<FileLock using file '/var/lib/cloud/instances/13862411-b73a-4aa1-9735-9ad34e302b41/sem/consume_data'>)
2016-01-28 15:47:15,090 - stages.py[DEBUG]: Added default handler for set(['text/cloud-config-jsonp', 'text/cloud-config']) from CloudConfigPartHandler: [['text/cloud-config', 'text/cloud-config-jsonp']]
2016-01-28 15:47:15,090 - stages.py[DEBUG]: Added default handler for set(['text/x-shellscript']) from ShellScriptPartHandler: [['text/x-shellscript']]
2016-01-28 15:47:15,090 - stages.py[DEBUG]: Added default handler for set(['text/cloud-boothook']) from BootHookPartHandler: [['text/cloud-boothook']]
2016-01-28 15:47:15,090 - stages.py[DEBUG]: Added default handler for set(['text/upstart-job']) from UpstartJobPartHandler: [['text/upstart-job']]
2016-01-28 15:47:15,091 - __init__.py[DEBUG]: Calling handler BootHookPartHandler: [['text/cloud-boothook']] (__begin__, None, 2) with frequency once-per-instance
2016-01-28 15:47:15,091 - __init__.py[DEBUG]: Calling handler UpstartJobPartHandler: [['text/upstart-job']] (__begin__, None, 2) with frequency once-per-instance
2016-01-28 15:47:15,091 - __init__.py[DEBUG]: Calling handler CloudConfigPartHandler: [['text/cloud-config', 'text/cloud-config-jsonp']] (__begin__, None, 3) with frequency once-per-instance
2016-01-28 15:47:15,091 - __init__.py[DEBUG]: Calling handler ShellScriptPartHandler: [['text/x-shellscript']] (__begin__, None, 2) with frequency once-per-instance
2016-01-28 15:47:15,091 - __init__.py[DEBUG]: {'Content-Transfer-Encoding': '7bit', 'Content-Type': 'text/cloud-config; charset="us-ascii"', 'Content-Disposition': 'attachment; filename="cloud-config"', 'MIME-Version': '1.0'}
2016-01-28 15:47:15,091 - __init__.py[DEBUG]: Calling handler CloudConfigPartHandler: [['text/cloud-config', 'text/cloud-config-jsonp']] (text/cloud-config, cloud-config, 3) with frequency once-per-instance
2016-01-28 15:47:15,092 - util.py[DEBUG]: Attempting to load yaml from string of length 153 with allowed root types (<type 'dict'>,)
2016-01-28 15:47:15,092 - cloud_config.py[DEBUG]: Merging by applying [('dict', ['replace']), ('list', []), ('str', [])]
2016-01-28 15:47:15,092 - importer.py[DEBUG]: Looking for modules ['cloudinit.mergers.m_dict'] that have attributes ['Merger']
2016-01-28 15:47:15,092 - importer.py[DEBUG]: Found m_dict with attributes ['Merger'] in ['cloudinit.mergers.m_dict']
2016-01-28 15:47:15,093 - importer.py[DEBUG]: Looking for modules ['cloudinit.mergers.m_list'] that have attributes ['Merger']
2016-01-28 15:47:15,093 - importer.py[DEBUG]: Found m_list with attributes ['Merger'] in ['cloudinit.mergers.m_list']
2016-01-28 15:47:15,093 - importer.py[DEBUG]: Looking for modules ['cloudinit.mergers.m_str'] that have attributes ['Merger']
2016-01-28 15:47:15,093 - importer.py[DEBUG]: Found m_str with attributes ['Merger'] in ['cloudinit.mergers.m_str']
2016-01-28 15:47:15,093 - __init__.py[DEBUG]: Merging 'dict' into 'dict' using method '_handle_unknown' of 'LookupMerger: (3)'
2016-01-28 15:47:15,093 - __init__.py[DEBUG]: Merging using located merger 'DictMerger: (method=replace,recurse_str=False,recurse_dict=True,recurse_array=False,allow_delete=False)' since it had method '_on_dict'
2016-01-28 15:47:15,093 - __init__.py[DEBUG]: {'Content-Transfer-Encoding': '7bit', 'Content-Type': 'text/cloud-boothook; charset="us-ascii"', 'Content-Disposition': 'attachment; filename="boothook.sh"', 'MIME-Version': '1.0'}
2016-01-28 15:47:15,093 - __init__.py[DEBUG]: Calling handler BootHookPartHandler: [['text/cloud-boothook']] (text/cloud-boothook, boothook.sh, 2) with frequency once-per-instance
2016-01-28 15:47:15,093 - util.py[DEBUG]: Writing to /var/lib/cloud/instances/13862411-b73a-4aa1-9735-9ad34e302b41/boothooks/boothook.sh - wb: [448] 534 bytes
2016-01-28 15:47:15,094 - util.py[DEBUG]: Running command ['/var/lib/cloud/instances/13862411-b73a-4aa1-9735-9ad34e302b41/boothooks/boothook.sh'] with allowed return codes [0] (shell=False, capture=True)
2016-01-28 15:47:15,097 - __init__.py[DEBUG]: {'Content-Transfer-Encoding': '7bit', 'Content-Type': 'text/part-handler; charset="us-ascii"', 'Content-Disposition': 'attachment; filename="part-handler.py"', 'MIME-Version': '1.0'}
2016-01-28 15:47:15,097 - util.py[DEBUG]: Writing to /var/lib/cloud/instances/13862411-b73a-4aa1-9735-9ad34e302b41/handlers/part-handler-000.py - wb: [384] 1530 bytes
2016-01-28 15:47:15,098 - __init__.py[DEBUG]: Calling handler <module 'part-handler-000' from '/var/lib/cloud/instances/13862411-b73a-4aa1-9735-9ad34e302b41/handlers/part-handler-000.py'> (__begin__, None, 1) with frequency once-per-instance
2016-01-28 15:47:15,098 - __init__.py[DEBUG]: {'Content-Transfer-Encoding': '7bit', 'Content-Type': 'text/x-shellscript; charset="us-ascii"', 'Content-Disposition': 'attachment; filename="userdata"', 'MIME-Version': '1.0'}
2016-01-28 15:47:15,098 - __init__.py[DEBUG]: Calling handler ShellScriptPartHandler: [['text/x-shellscript']] (text/x-shellscript, userdata, 2) with frequency once-per-instance
2016-01-28 15:47:15,099 - util.py[DEBUG]: Writing to /var/lib/cloud/instance/scripts/userdata - wb: [448] 0 bytes
2016-01-28 15:47:15,099 - __init__.py[DEBUG]: {'Content-Transfer-Encoding': '7bit', 'Content-Type': 'text/x-cfninitdata; charset="us-ascii"', 'Content-Disposition': 'attachment; filename="cfn-init-data"', 'MIME-Version': '1.0'}
2016-01-28 15:47:15,099 - __init__.py[DEBUG]: Calling handler <module 'part-handler-000' from '/var/lib/cloud/instances/13862411-b73a-4aa1-9735-9ad34e302b41/handlers/part-handler-000.py'> (text/x-cfninitdata, cfn-init-data, 1) with frequency once-per-instance
2016-01-28 15:47:15,099 - __init__.py[DEBUG]: {'Content-Transfer-Encoding': '7bit', 'Content-Type': 'text/x-cfninitdata; charset="us-ascii"', 'Content-Disposition': 'attachment; filename="cfn-watch-server"', 'MIME-Version': '1.0'}
2016-01-28 15:47:15,099 - __init__.py[DEBUG]: Calling handler <module 'part-handler-000' from '/var/lib/cloud/instances/13862411-b73a-4aa1-9735-9ad34e302b41/handlers/part-handler-000.py'> (text/x-cfninitdata, cfn-watch-server, 1) with frequency once-per-instance
2016-01-28 15:47:15,100 - __init__.py[DEBUG]: Calling handler <module 'part-handler-000' from '/var/lib/cloud/instances/13862411-b73a-4aa1-9735-9ad34e302b41/handlers/part-handler-000.py'> (__end__, None, 1) with frequency once-per-instance
2016-01-28 15:47:15,100 - __init__.py[DEBUG]: Calling handler ShellScriptPartHandler: [['text/x-shellscript']] (__end__, None, 2) with frequency once-per-instance
2016-01-28 15:47:15,100 - __init__.py[DEBUG]: Calling handler BootHookPartHandler: [['text/cloud-boothook']] (__end__, None, 2) with frequency once-per-instance
2016-01-28 15:47:15,100 - __init__.py[DEBUG]: Calling handler UpstartJobPartHandler: [['text/upstart-job']] (__end__, None, 2) with frequency once-per-instance
2016-01-28 15:47:15,100 - __init__.py[DEBUG]: Calling handler CloudConfigPartHandler: [['text/cloud-config', 'text/cloud-config-jsonp']] (__end__, None, 3) with frequency once-per-instance
2016-01-28 15:47:15,101 - util.py[DEBUG]: Writing to /var/lib/cloud/instances/13862411-b73a-4aa1-9735-9ad34e302b41/cloud-config.txt - wb: [384] 113 bytes
2016-01-28 15:47:15,101 - stages.py[DEBUG]: no vendordata from datasource
2016-01-28 15:47:15,101 - util.py[DEBUG]: Reading from /proc/cmdline (quiet=False)
2016-01-28 15:47:15,102 - util.py[DEBUG]: Read 123 bytes from /proc/cmdline
2016-01-28 15:47:15,102 - util.py[DEBUG]: Reading from /etc/cloud/cloud.cfg (quiet=False)
2016-01-28 15:47:15,102 - util.py[DEBUG]: Read 2960 bytes from /etc/cloud/cloud.cfg
2016-01-28 15:47:15,102 - util.py[DEBUG]: Attempting to load yaml from string of length 2960 with allowed root types (<type 'dict'>,)
2016-01-28 15:47:15,115 - util.py[DEBUG]: Reading from /etc/cloud/cloud.cfg.d/90_dpkg.cfg (quiet=False)
2016-01-28 15:47:15,116 - util.py[DEBUG]: Read 94 bytes from /etc/cloud/cloud.cfg.d/90_dpkg.cfg
2016-01-28 15:47:15,116 - util.py[DEBUG]: Attempting to load yaml from string of length 94 with allowed root types (<type 'dict'>,)
2016-01-28 15:47:15,116 - util.py[DEBUG]: Reading from /etc/cloud/cloud.cfg.d/10_rackspace.cfg (quiet=False)
2016-01-28 15:47:15,117 - util.py[DEBUG]: Read 114 bytes from /etc/cloud/cloud.cfg.d/10_rackspace.cfg
2016-01-28 15:47:15,117 - util.py[DEBUG]: Attempting to load yaml from string of length 114 with allowed root types (<type 'dict'>,)
2016-01-28 15:47:15,118 - util.py[DEBUG]: Reading from /etc/cloud/cloud.cfg.d/05_logging.cfg (quiet=False)
2016-01-28 15:47:15,118 - util.py[DEBUG]: Read 1910 bytes from /etc/cloud/cloud.cfg.d/05_logging.cfg
2016-01-28 15:47:15,118 - util.py[DEBUG]: Attempting to load yaml from string of length 1910 with allowed root types (<type 'dict'>,)
2016-01-28 15:47:15,122 - importer.py[DEBUG]: Looking for modules ['cloudinit.mergers.m_list'] that have attributes ['Merger']
2016-01-28 15:47:15,122 - importer.py[DEBUG]: Found m_list with attributes ['Merger'] in ['cloudinit.mergers.m_list']
2016-01-28 15:47:15,122 - importer.py[DEBUG]: Looking for modules ['cloudinit.mergers.m_dict'] that have attributes ['Merger']
2016-01-28 15:47:15,122 - importer.py[DEBUG]: Found m_dict with attributes ['Merger'] in ['cloudinit.mergers.m_dict']
2016-01-28 15:47:15,122 - importer.py[DEBUG]: Looking for modules ['cloudinit.mergers.m_str'] that have attributes ['Merger']
2016-01-28 15:47:15,122 - importer.py[DEBUG]: Found m_str with attributes ['Merger'] in ['cloudinit.mergers.m_str']
2016-01-28 15:47:15,122 - __init__.py[DEBUG]: Merging 'dict' into 'dict' using method '_handle_unknown' of 'LookupMerger: (3)'
2016-01-28 15:47:15,122 - __init__.py[DEBUG]: Merging using located merger 'DictMerger: (method=no_replace,recurse_str=False,recurse_dict=True,recurse_array=False,allow_delete=False)' since it had method '_on_dict'
2016-01-28 15:47:15,123 - importer.py[DEBUG]: Looking for modules ['cloudinit.mergers.m_list'] that have attributes ['Merger']
2016-01-28 15:47:15,123 - importer.py[DEBUG]: Found m_list with attributes ['Merger'] in ['cloudinit.mergers.m_list']
2016-01-28 15:47:15,123 - importer.py[DEBUG]: Looking for modules ['cloudinit.mergers.m_dict'] that have attributes ['Merger']
2016-01-28 15:47:15,123 - importer.py[DEBUG]: Found m_dict with attributes ['Merger'] in ['cloudinit.mergers.m_dict']
2016-01-28 15:47:15,123 - importer.py[DEBUG]: Looking for modules ['cloudinit.mergers.m_str'] that have attributes ['Merger']
2016-01-28 15:47:15,123 - importer.py[DEBUG]: Found m_str with attributes ['Merger'] in ['cloudinit.mergers.m_str']
2016-01-28 15:47:15,123 - __init__.py[DEBUG]: Merging 'dict' into 'dict' using method '_handle_unknown' of 'LookupMerger: (3)'
2016-01-28 15:47:15,123 - __init__.py[DEBUG]: Merging using located merger 'DictMerger: (method=no_replace,recurse_str=False,recurse_dict=True,recurse_array=False,allow_delete=False)' since it had method '_on_dict'
2016-01-28 15:47:15,123 - importer.py[DEBUG]: Looking for modules ['cloudinit.mergers.m_list'] that have attributes ['Merger']
2016-01-28 15:47:15,123 - importer.py[DEBUG]: Found m_list with attributes ['Merger'] in ['cloudinit.mergers.m_list']
2016-01-28 15:47:15,123 - importer.py[DEBUG]: Looking for modules ['cloudinit.mergers.m_dict'] that have attributes ['Merger']
2016-01-28 15:47:15,123 - importer.py[DEBUG]: Found m_dict with attributes ['Merger'] in ['cloudinit.mergers.m_dict']
2016-01-28 15:47:15,123 - importer.py[DEBUG]: Looking for modules ['cloudinit.mergers.m_str'] that have attributes ['Merger']
2016-01-28 15:47:15,124 - importer.py[DEBUG]: Found m_str with attributes ['Merger'] in ['cloudinit.mergers.m_str']
2016-01-28 15:47:15,124 - __init__.py[DEBUG]: Merging 'dict' into 'dict' using method '_handle_unknown' of 'LookupMerger: (3)'
2016-01-28 15:47:15,124 - __init__.py[DEBUG]: Merging using located merger 'DictMerger: (method=no_replace,recurse_str=False,recurse_dict=True,recurse_array=False,allow_delete=False)' since it had method '_on_dict'
2016-01-28 15:47:15,124 - importer.py[DEBUG]: Looking for modules ['cloudinit.mergers.m_list'] that have attributes ['Merger']
2016-01-28 15:47:15,124 - importer.py[DEBUG]: Found m_list with attributes ['Merger'] in ['cloudinit.mergers.m_list']
2016-01-28 15:47:15,124 - importer.py[DEBUG]: Looking for modules ['cloudinit.mergers.m_dict'] that have attributes ['Merger']
2016-01-28 15:47:15,124 - importer.py[DEBUG]: Found m_dict with attributes ['Merger'] in ['cloudinit.mergers.m_dict']
2016-01-28 15:47:15,124 - importer.py[DEBUG]: Looking for modules ['cloudinit.mergers.m_str'] that have attributes ['Merger']
2016-01-28 15:47:15,124 - importer.py[DEBUG]: Found m_str with attributes ['Merger'] in ['cloudinit.mergers.m_str']
2016-01-28 15:47:15,124 - __init__.py[DEBUG]: Merging 'dict' into 'dict' using method '_handle_unknown' of 'LookupMerger: (3)'
2016-01-28 15:47:15,124 - __init__.py[DEBUG]: Merging using located merger 'DictMerger: (method=no_replace,recurse_str=False,recurse_dict=True,recurse_array=False,allow_delete=False)' since it had method '_on_dict'
2016-01-28 15:47:15,124 - importer.py[DEBUG]: Looking for modules ['cloudinit.mergers.m_list'] that have attributes ['Merger']
2016-01-28 15:47:15,124 - importer.py[DEBUG]: Found m_list with attributes ['Merger'] in ['cloudinit.mergers.m_list']
2016-01-28 15:47:15,124 - importer.py[DEBUG]: Looking for modules ['cloudinit.mergers.m_dict'] that have attributes ['Merger']
2016-01-28 15:47:15,125 - importer.py[DEBUG]: Found m_dict with attributes ['Merger'] in ['cloudinit.mergers.m_dict']
2016-01-28 15:47:15,125 - importer.py[DEBUG]: Looking for modules ['cloudinit.mergers.m_str'] that have attributes ['Merger']
2016-01-28 15:47:15,125 - importer.py[DEBUG]: Found m_str with attributes ['Merger'] in ['cloudinit.mergers.m_str']
2016-01-28 15:47:15,125 - __init__.py[DEBUG]: Merging 'dict' into 'dict' using method '_handle_unknown' of 'LookupMerger: (3)'
2016-01-28 15:47:15,125 - __init__.py[DEBUG]: Merging using located merger 'DictMerger: (method=no_replace,recurse_str=False,recurse_dict=True,recurse_array=False,allow_delete=False)' since it had method '_on_dict'
2016-01-28 15:47:15,125 - importer.py[DEBUG]: Looking for modules ['cloudinit.mergers.m_list'] that have attributes ['Merger']
2016-01-28 15:47:15,125 - importer.py[DEBUG]: Found m_list with attributes ['Merger'] in ['cloudinit.mergers.m_list']
2016-01-28 15:47:15,125 - importer.py[DEBUG]: Looking for modules ['cloudinit.mergers.m_dict'] that have attributes ['Merger']
2016-01-28 15:47:15,125 - importer.py[DEBUG]: Found m_dict with attributes ['Merger'] in ['cloudinit.mergers.m_dict']
2016-01-28 15:47:15,125 - importer.py[DEBUG]: Looking for modules ['cloudinit.mergers.m_str'] that have attributes ['Merger']
2016-01-28 15:47:15,125 - importer.py[DEBUG]: Found m_str with attributes ['Merger'] in ['cloudinit.mergers.m_str']
2016-01-28 15:47:15,125 - __init__.py[DEBUG]: Merging 'dict' into 'dict' using method '_handle_unknown' of 'LookupMerger: (3)'
2016-01-28 15:47:15,125 - __init__.py[DEBUG]: Merging using located merger 'DictMerger: (method=no_replace,recurse_str=False,recurse_dict=True,recurse_array=False,allow_delete=False)' since it had method '_on_dict'
2016-01-28 15:47:15,125 - importer.py[DEBUG]: Looking for modules ['cloudinit.mergers.m_list'] that have attributes ['Merger']
2016-01-28 15:47:15,126 - importer.py[DEBUG]: Found m_list with attributes ['Merger'] in ['cloudinit.mergers.m_list']
2016-01-28 15:47:15,126 - importer.py[DEBUG]: Looking for modules ['cloudinit.mergers.m_dict'] that have attributes ['Merger']
2016-01-28 15:47:15,126 - importer.py[DEBUG]: Found m_dict with attributes ['Merger'] in ['cloudinit.mergers.m_dict']
2016-01-28 15:47:15,126 - importer.py[DEBUG]: Looking for modules ['cloudinit.mergers.m_str'] that have attributes ['Merger']
2016-01-28 15:47:15,126 - importer.py[DEBUG]: Found m_str with attributes ['Merger'] in ['cloudinit.mergers.m_str']
2016-01-28 15:47:15,126 - __init__.py[DEBUG]: Merging 'dict' into 'dict' using method '_handle_unknown' of 'LookupMerger: (3)'
2016-01-28 15:47:15,126 - __init__.py[DEBUG]: Merging using located merger 'DictMerger: (method=no_replace,recurse_str=False,recurse_dict=True,recurse_array=False,allow_delete=False)' since it had method '_on_dict'
2016-01-28 15:47:15,126 - __init__.py[DEBUG]: Merging 'dict' into 'dict' using method '_handle_unknown' of 'LookupMerger: (3)'
2016-01-28 15:47:15,126 - __init__.py[DEBUG]: Merging using located merger 'DictMerger: (method=no_replace,recurse_str=False,recurse_dict=True,recurse_array=False,allow_delete=False)' since it had method '_on_dict'
2016-01-28 15:47:15,126 - __init__.py[DEBUG]: Merging 'dict' into 'dict' using method '_handle_unknown' of 'LookupMerger: (3)'
2016-01-28 15:47:15,126 - __init__.py[DEBUG]: Merging using located merger 'DictMerger: (method=no_replace,recurse_str=False,recurse_dict=True,recurse_array=False,allow_delete=False)' since it had method '_on_dict'
2016-01-28 15:47:15,126 - util.py[DEBUG]: Reading from /var/lib/cloud/instance/cloud-config.txt (quiet=False)
2016-01-28 15:47:15,127 - util.py[DEBUG]: Read 113 bytes from /var/lib/cloud/instance/cloud-config.txt
2016-01-28 15:47:15,127 - util.py[DEBUG]: Attempting to load yaml from string of length 113 with allowed root types (<type 'dict'>,)
2016-01-28 15:47:15,127 - importer.py[DEBUG]: Looking for modules ['cloudinit.mergers.m_list'] that have attributes ['Merger']
2016-01-28 15:47:15,128 - importer.py[DEBUG]: Found m_list with attributes ['Merger'] in ['cloudinit.mergers.m_list']
2016-01-28 15:47:15,128 - importer.py[DEBUG]: Looking for modules ['cloudinit.mergers.m_dict'] that have attributes ['Merger']
2016-01-28 15:47:15,128 - importer.py[DEBUG]: Found m_dict with attributes ['Merger'] in ['cloudinit.mergers.m_dict']
2016-01-28 15:47:15,128 - importer.py[DEBUG]: Looking for modules ['cloudinit.mergers.m_str'] that have attributes ['Merger']
2016-01-28 15:47:15,128 - importer.py[DEBUG]: Found m_str with attributes ['Merger'] in ['cloudinit.mergers.m_str']
2016-01-28 15:47:15,128 - __init__.py[DEBUG]: Merging 'dict' into 'dict' using method '_handle_unknown' of 'LookupMerger: (3)'
2016-01-28 15:47:15,128 - __init__.py[DEBUG]: Merging using located merger 'DictMerger: (method=no_replace,recurse_str=False,recurse_dict=True,recurse_array=False,allow_delete=False)' since it had method '_on_dict'
2016-01-28 15:47:15,128 - importer.py[DEBUG]: Looking for modules ['cloudinit.mergers.m_list'] that have attributes ['Merger']
2016-01-28 15:47:15,128 - importer.py[DEBUG]: Found m_list with attributes ['Merger'] in ['cloudinit.mergers.m_list']
2016-01-28 15:47:15,128 - importer.py[DEBUG]: Looking for modules ['cloudinit.mergers.m_dict'] that have attributes ['Merger']
2016-01-28 15:47:15,128 - importer.py[DEBUG]: Found m_dict with attributes ['Merger'] in ['cloudinit.mergers.m_dict']
2016-01-28 15:47:15,128 - importer.py[DEBUG]: Looking for modules ['cloudinit.mergers.m_str'] that have attributes ['Merger']
2016-01-28 15:47:15,128 - importer.py[DEBUG]: Found m_str with attributes ['Merger'] in ['cloudinit.mergers.m_str']
2016-01-28 15:47:15,128 - __init__.py[DEBUG]: Merging 'dict' into 'dict' using method '_handle_unknown' of 'LookupMerger: (3)'
2016-01-28 15:47:15,129 - __init__.py[DEBUG]: Merging using located merger 'DictMerger: (method=no_replace,recurse_str=False,recurse_dict=True,recurse_array=False,allow_delete=False)' since it had method '_on_dict'
2016-01-28 15:47:15,129 - __init__.py[DEBUG]: Merging 'dict' into 'dict' using method '_handle_unknown' of 'LookupMerger: (3)'
2016-01-28 15:47:15,129 - __init__.py[DEBUG]: Merging using located merger 'DictMerger: (method=no_replace,recurse_str=False,recurse_dict=True,recurse_array=False,allow_delete=False)' since it had method '_on_dict'
2016-01-28 15:47:15,129 - util.py[DEBUG]: Reading from /var/lib/cloud/instance/cloud-config.txt (quiet=False)
2016-01-28 15:47:15,129 - util.py[DEBUG]: Read 113 bytes from /var/lib/cloud/instance/cloud-config.txt
2016-01-28 15:47:15,130 - util.py[DEBUG]: Attempting to load yaml from string of length 113 with allowed root types (<type 'dict'>,)
2016-01-28 15:47:15,130 - importer.py[DEBUG]: Looking for modules ['cloudinit.mergers.m_list'] that have attributes ['Merger']
2016-01-28 15:47:15,130 - importer.py[DEBUG]: Found m_list with attributes ['Merger'] in ['cloudinit.mergers.m_list']
2016-01-28 15:47:15,131 - importer.py[DEBUG]: Looking for modules ['cloudinit.mergers.m_dict'] that have attributes ['Merger']
2016-01-28 15:47:15,131 - importer.py[DEBUG]: Found m_dict with attributes ['Merger'] in ['cloudinit.mergers.m_dict']
2016-01-28 15:47:15,131 - importer.py[DEBUG]: Looking for modules ['cloudinit.mergers.m_str'] that have attributes ['Merger']
2016-01-28 15:47:15,131 - importer.py[DEBUG]: Found m_str with attributes ['Merger'] in ['cloudinit.mergers.m_str']
2016-01-28 15:47:15,131 - __init__.py[DEBUG]: Merging 'dict' into 'dict' using method '_handle_unknown' of 'LookupMerger: (3)'
2016-01-28 15:47:15,131 - __init__.py[DEBUG]: Merging using located merger 'DictMerger: (method=no_replace,recurse_str=False,recurse_dict=True,recurse_array=False,allow_delete=False)' since it had method '_on_dict'
2016-01-28 15:47:15,131 - importer.py[DEBUG]: Looking for modules ['cloudinit.mergers.m_list'] that have attributes ['Merger']
2016-01-28 15:47:15,131 - importer.py[DEBUG]: Found m_list with attributes ['Merger'] in ['cloudinit.mergers.m_list']
2016-01-28 15:47:15,131 - importer.py[DEBUG]: Looking for modules ['cloudinit.mergers.m_dict'] that have attributes ['Merger']
2016-01-28 15:47:15,131 - importer.py[DEBUG]: Found m_dict with attributes ['Merger'] in ['cloudinit.mergers.m_dict']
2016-01-28 15:47:15,131 - importer.py[DEBUG]: Looking for modules ['cloudinit.mergers.m_str'] that have attributes ['Merger']
2016-01-28 15:47:15,131 - importer.py[DEBUG]: Found m_str with attributes ['Merger'] in ['cloudinit.mergers.m_str']
2016-01-28 15:47:15,132 - __init__.py[DEBUG]: Merging 'dict' into 'dict' using method '_handle_unknown' of 'LookupMerger: (3)'
2016-01-28 15:47:15,132 - __init__.py[DEBUG]: Merging using located merger 'DictMerger: (method=no_replace,recurse_str=False,recurse_dict=True,recurse_array=False,allow_delete=False)' since it had method '_on_dict'
2016-01-28 15:47:15,132 - __init__.py[DEBUG]: Merging 'dict' into 'dict' using method '_handle_unknown' of 'LookupMerger: (3)'
2016-01-28 15:47:15,132 - __init__.py[DEBUG]: Merging using located merger 'DictMerger: (method=no_replace,recurse_str=False,recurse_dict=True,recurse_array=False,allow_delete=False)' since it had method '_on_dict'
2016-01-28 15:47:15,135 - importer.py[DEBUG]: Looking for modules ['cc_migrator', 'cloudinit.config.cc_migrator'] that have attributes ['handle']
2016-01-28 15:47:15,135 - importer.py[DEBUG]: Failed at attempted import of 'cc_migrator' due to: No module named cc_migrator
2016-01-28 15:47:15,136 - importer.py[DEBUG]: Found cc_migrator with attributes ['handle'] in ['cloudinit.config.cc_migrator']
2016-01-28 15:47:15,136 - importer.py[DEBUG]: Looking for modules ['cc_seed_random', 'cloudinit.config.cc_seed_random'] that have attributes ['handle']
2016-01-28 15:47:15,136 - importer.py[DEBUG]: Failed at attempted import of 'cc_seed_random' due to: No module named cc_seed_random
2016-01-28 15:47:15,137 - importer.py[DEBUG]: Found cc_seed_random with attributes ['handle'] in ['cloudinit.config.cc_seed_random']
2016-01-28 15:47:15,137 - importer.py[DEBUG]: Looking for modules ['cc_bootcmd', 'cloudinit.config.cc_bootcmd'] that have attributes ['handle']
2016-01-28 15:47:15,137 - importer.py[DEBUG]: Failed at attempted import of 'cc_bootcmd' due to: No module named cc_bootcmd
2016-01-28 15:47:15,137 - importer.py[DEBUG]: Found cc_bootcmd with attributes ['handle'] in ['cloudinit.config.cc_bootcmd']
2016-01-28 15:47:15,137 - importer.py[DEBUG]: Looking for modules ['cc_write_files', 'cloudinit.config.cc_write_files'] that have attributes ['handle']
2016-01-28 15:47:15,138 - importer.py[DEBUG]: Failed at attempted import of 'cc_write_files' due to: No module named cc_write_files
2016-01-28 15:47:15,138 - importer.py[DEBUG]: Found cc_write_files with attributes ['handle'] in ['cloudinit.config.cc_write_files']
2016-01-28 15:47:15,138 - importer.py[DEBUG]: Looking for modules ['cc_growpart', 'cloudinit.config.cc_growpart'] that have attributes ['handle']
2016-01-28 15:47:15,138 - importer.py[DEBUG]: Failed at attempted import of 'cc_growpart' due to: No module named cc_growpart
2016-01-28 15:47:15,139 - importer.py[DEBUG]: Found cc_growpart with attributes ['handle'] in ['cloudinit.config.cc_growpart']
2016-01-28 15:47:15,139 - importer.py[DEBUG]: Looking for modules ['cc_resizefs', 'cloudinit.config.cc_resizefs'] that have attributes ['handle']
2016-01-28 15:47:15,140 - importer.py[DEBUG]: Failed at attempted import of 'cc_resizefs' due to: No module named cc_resizefs
2016-01-28 15:47:15,140 - importer.py[DEBUG]: Found cc_resizefs with attributes ['handle'] in ['cloudinit.config.cc_resizefs']
2016-01-28 15:47:15,140 - importer.py[DEBUG]: Looking for modules ['cc_set_hostname', 'cloudinit.config.cc_set_hostname'] that have attributes ['handle']
2016-01-28 15:47:15,140 - importer.py[DEBUG]: Failed at attempted import of 'cc_set_hostname' due to: No module named cc_set_hostname
2016-01-28 15:47:15,141 - importer.py[DEBUG]: Found cc_set_hostname with attributes ['handle'] in ['cloudinit.config.cc_set_hostname']
2016-01-28 15:47:15,141 - importer.py[DEBUG]: Looking for modules ['cc_update_hostname', 'cloudinit.config.cc_update_hostname'] that have attributes ['handle']
2016-01-28 15:47:15,141 - importer.py[DEBUG]: Failed at attempted import of 'cc_update_hostname' due to: No module named cc_update_hostname
2016-01-28 15:47:15,142 - importer.py[DEBUG]: Found cc_update_hostname with attributes ['handle'] in ['cloudinit.config.cc_update_hostname']
2016-01-28 15:47:15,142 - importer.py[DEBUG]: Looking for modules ['cc_update_etc_hosts', 'cloudinit.config.cc_update_etc_hosts'] that have attributes ['handle']
2016-01-28 15:47:15,142 - importer.py[DEBUG]: Failed at attempted import of 'cc_update_etc_hosts' due to: No module named cc_update_etc_hosts
2016-01-28 15:47:15,142 - importer.py[DEBUG]: Found cc_update_etc_hosts with attributes ['handle'] in ['cloudinit.config.cc_update_etc_hosts']
2016-01-28 15:47:15,142 - importer.py[DEBUG]: Looking for modules ['cc_ca_certs', 'cloudinit.config.cc_ca_certs'] that have attributes ['handle']
2016-01-28 15:47:15,143 - importer.py[DEBUG]: Failed at attempted import of 'cc_ca_certs' due to: No module named cc_ca_certs
2016-01-28 15:47:15,143 - importer.py[DEBUG]: Found cc_ca_certs with attributes ['handle'] in ['cloudinit.config.cc_ca_certs']
2016-01-28 15:47:15,143 - importer.py[DEBUG]: Looking for modules ['cc_rsyslog', 'cloudinit.config.cc_rsyslog'] that have attributes ['handle']
2016-01-28 15:47:15,144 - importer.py[DEBUG]: Failed at attempted import of 'cc_rsyslog' due to: No module named cc_rsyslog
2016-01-28 15:47:15,144 - importer.py[DEBUG]: Found cc_rsyslog with attributes ['handle'] in ['cloudinit.config.cc_rsyslog']
2016-01-28 15:47:15,144 - importer.py[DEBUG]: Looking for modules ['cc_users_groups', 'cloudinit.config.cc_users_groups'] that have attributes ['handle']
2016-01-28 15:47:15,145 - importer.py[DEBUG]: Failed at attempted import of 'cc_users_groups' due to: No module named cc_users_groups
2016-01-28 15:47:15,145 - importer.py[DEBUG]: Found cc_users_groups with attributes ['handle'] in ['cloudinit.config.cc_users_groups']
2016-01-28 15:47:15,145 - importer.py[DEBUG]: Looking for modules ['cc_ssh', 'cloudinit.config.cc_ssh'] that have attributes ['handle']
2016-01-28 15:47:15,145 - importer.py[DEBUG]: Failed at attempted import of 'cc_ssh' due to: No module named cc_ssh
2016-01-28 15:47:15,146 - importer.py[DEBUG]: Found cc_ssh with attributes ['handle'] in ['cloudinit.config.cc_ssh']
2016-01-28 15:47:15,146 - importer.py[DEBUG]: Looking for modules ['ubuntu', 'cloudinit.distros.ubuntu'] that have attributes ['Distro']
2016-01-28 15:47:15,146 - importer.py[DEBUG]: Failed at attempted import of 'ubuntu' due to: No module named ubuntu
2016-01-28 15:47:15,146 - importer.py[DEBUG]: Found ubuntu with attributes ['Distro'] in ['cloudinit.distros.ubuntu']
2016-01-28 15:47:15,146 - stages.py[DEBUG]: Using distro class <class 'cloudinit.distros.ubuntu.Distro'>
2016-01-28 15:47:15,147 - helpers.py[DEBUG]: Running config-migrator using lock (<cloudinit.helpers.DummyLock object at 0x7fcd7f0b4dd0>)
2016-01-28 15:47:15,147 - cc_migrator.py[DEBUG]: Migrated 0 semaphore files to there canonicalized names
2016-01-28 15:47:15,148 - util.py[DEBUG]: Writing to /var/lib/cloud/instances/13862411-b73a-4aa1-9735-9ad34e302b41/sem/config_seed_random - wb: [420] 20 bytes
2016-01-28 15:47:15,148 - helpers.py[DEBUG]: Running config-seed_random using lock (<FileLock using file '/var/lib/cloud/instances/13862411-b73a-4aa1-9735-9ad34e302b41/sem/config_seed_random'>)
2016-01-28 15:47:15,148 - cc_seed_random.py[DEBUG]: command 'pollinate' not found for seed_command
2016-01-28 15:47:15,148 - helpers.py[DEBUG]: Running config-bootcmd using lock (<cloudinit.helpers.DummyLock object at 0x7fcd7f0c0650>)
2016-01-28 15:47:15,149 - cc_bootcmd.py[DEBUG]: Skipping module named bootcmd, no 'bootcmd' key in configuration
2016-01-28 15:47:15,149 - util.py[DEBUG]: Writing to /var/lib/cloud/instances/13862411-b73a-4aa1-9735-9ad34e302b41/sem/config_write_files - wb: [420] 20 bytes
2016-01-28 15:47:15,149 - helpers.py[DEBUG]: Running config-write-files using lock (<FileLock using file '/var/lib/cloud/instances/13862411-b73a-4aa1-9735-9ad34e302b41/sem/config_write_files'>)
2016-01-28 15:47:15,149 - cc_write_files.py[DEBUG]: Skipping module named write-files, no/empty 'write_files' key in configuration
2016-01-28 15:47:15,149 - helpers.py[DEBUG]: Running config-growpart using lock (<cloudinit.helpers.DummyLock object at 0x7fcd7f0c0650>)
2016-01-28 15:47:15,149 - cc_growpart.py[DEBUG]: No 'growpart' entry in cfg.  Using default: {'ignore_growroot_disabled': False, 'mode': 'auto', 'devices': ['/']}
2016-01-28 15:47:15,150 - util.py[DEBUG]: Running command ['growpart', '--help'] with allowed return codes [0] (shell=False, capture=True)
2016-01-28 15:47:15,154 - util.py[DEBUG]: Reading from /proc/1041/mountinfo (quiet=False)
2016-01-28 15:47:15,154 - util.py[DEBUG]: Read 1099 bytes from /proc/1041/mountinfo
2016-01-28 15:47:15,156 - util.py[DEBUG]: Reading from /sys/class/block/xvda1/partition (quiet=False)
2016-01-28 15:47:15,156 - util.py[DEBUG]: Read 2 bytes from /sys/class/block/xvda1/partition
2016-01-28 15:47:15,156 - util.py[DEBUG]: Reading from /sys/devices/vbd-768/block/xvda/dev (quiet=False)
2016-01-28 15:47:15,156 - util.py[DEBUG]: Read 6 bytes from /sys/devices/vbd-768/block/xvda/dev
2016-01-28 15:47:15,157 - util.py[DEBUG]: Running command ['growpart', '--dry-run', '/dev/xvda', '1'] with allowed return codes [0] (shell=False, capture=True)
2016-01-28 15:47:15,173 - util.py[DEBUG]: resize_devices took 0.019 seconds
2016-01-28 15:47:15,173 - cc_growpart.py[DEBUG]: '/' NOCHANGE: no change necessary (/dev/xvda, 1)
2016-01-28 15:47:15,173 - helpers.py[DEBUG]: Running config-resizefs using lock (<cloudinit.helpers.DummyLock object at 0x7fcd7f0c0650>)
2016-01-28 15:47:15,173 - util.py[DEBUG]: Reading from /proc/1041/mountinfo (quiet=False)
2016-01-28 15:47:15,173 - util.py[DEBUG]: Read 1099 bytes from /proc/1041/mountinfo
2016-01-28 15:47:15,174 - cc_resizefs.py[DEBUG]: resize_info: dev=/dev/xvda1 mnt_point=/ path=/
2016-01-28 15:47:15,174 - util.py[DEBUG]: Running command ['running-in-container'] with allowed return codes [0] (shell=False, capture=True)
2016-01-28 15:47:15,179 - util.py[DEBUG]: Running command ['lxc-is-container'] with allowed return codes [0] (shell=False, capture=True)
2016-01-28 15:47:15,184 - util.py[DEBUG]: Reading from /proc/1/environ (quiet=False)
2016-01-28 15:47:15,184 - util.py[DEBUG]: Read 163 bytes from /proc/1/environ
2016-01-28 15:47:15,184 - util.py[DEBUG]: Reading from /proc/self/status (quiet=False)
2016-01-28 15:47:15,184 - util.py[DEBUG]: Read 782 bytes from /proc/self/status
2016-01-28 15:47:15,184 - cc_resizefs.py[DEBUG]: Resizing / (ext4) using resize2fs /dev/xvda1
2016-01-28 15:47:15,185 - util.py[DEBUG]: Running command ('resize2fs', '/dev/xvda1') with allowed return codes [0] (shell=False, capture=True)
2016-01-28 15:47:15,189 - util.py[DEBUG]: backgrounded Resizing took 0.005 seconds
2016-01-28 15:47:15,190 - util.py[DEBUG]: Forked child 1145 who will run callback NoneType
2016-01-28 15:47:15,190 - cc_resizefs.py[DEBUG]: Resizing (via forking) root filesystem (type=ext4, val=noblock)
2016-01-28 15:47:15,191 - util.py[DEBUG]: Writing to /var/lib/cloud/instances/13862411-b73a-4aa1-9735-9ad34e302b41/sem/config_set_hostname - wb: [420] 20 bytes
2016-01-28 15:47:15,191 - helpers.py[DEBUG]: Running config-set_hostname using lock (<FileLock using file '/var/lib/cloud/instances/13862411-b73a-4aa1-9735-9ad34e302b41/sem/config_set_hostname'>)
2016-01-28 15:47:15,191 - cc_set_hostname.py[DEBUG]: Setting the hostname to one-click-build-test-1453995898-67.localdomain (one-click-build-test-1453995898-67)
2016-01-28 15:47:15,192 - util.py[DEBUG]: Reading from /etc/hostname (quiet=False)
2016-01-28 15:47:15,192 - util.py[DEBUG]: Read 35 bytes from /etc/hostname
2016-01-28 15:47:15,192 - util.py[DEBUG]: Writing to /etc/hostname - wb: [420] 35 bytes
2016-01-28 15:47:15,192 - __init__.py[DEBUG]: Non-persistently setting the system hostname to one-click-build-test-1453995898-67
2016-01-28 15:47:15,192 - util.py[DEBUG]: Running command ['hostname', u'one-click-build-test-1453995898-67'] with allowed return codes [0] (shell=False, capture=True)
2016-01-28 15:47:15,195 - util.py[WARNING]: Failed forking and calling callback NoneType
2016-01-28 15:47:15,196 - helpers.py[DEBUG]: Running config-update_hostname using lock (<cloudinit.helpers.DummyLock object at 0x7fcd7f0c0d90>)
2016-01-28 15:47:15,196 - cc_update_hostname.py[DEBUG]: Updating hostname to one-click-build-test-1453995898-67.localdomain (one-click-build-test-1453995898-67)
2016-01-28 15:47:15,196 - util.py[DEBUG]: Reading from /etc/hostname (quiet=False)
2016-01-28 15:47:15,197 - util.py[DEBUG]: Read 35 bytes from /etc/hostname
2016-01-28 15:47:15,197 - __init__.py[DEBUG]: Attempting to update hostname to one-click-build-test-1453995898-67 in 1 files
2016-01-28 15:47:15,197 - util.py[DEBUG]: Reading from /var/lib/cloud/data/previous-hostname (quiet=False)
2016-01-28 15:47:15,197 - util.py[DEBUG]: Writing to /var/lib/cloud/data/previous-hostname - wb: [420] 35 bytes
2016-01-28 15:47:15,197 - helpers.py[DEBUG]: Running config-update_etc_hosts using lock (<cloudinit.helpers.DummyLock object at 0x7fcd7f0c0e90>)
2016-01-28 15:47:15,197 - cc_update_etc_hosts.py[DEBUG]: Configuration option 'manage_etc_hosts' is not set, not managing /etc/hosts in module update_etc_hosts
2016-01-28 15:47:15,198 - util.py[DEBUG]: Writing to /var/lib/cloud/instances/13862411-b73a-4aa1-9735-9ad34e302b41/sem/config_ca_certs - wb: [420] 19 bytes
2016-01-28 15:47:15,198 - helpers.py[DEBUG]: Running config-ca-certs using lock (<FileLock using file '/var/lib/cloud/instances/13862411-b73a-4aa1-9735-9ad34e302b41/sem/config_ca_certs'>)
2016-01-28 15:47:15,198 - cc_ca_certs.py[DEBUG]: Skipping module named ca-certs, no 'ca-certs' key in configuration
2016-01-28 15:47:15,198 - util.py[DEBUG]: Writing to /var/lib/cloud/instances/13862411-b73a-4aa1-9735-9ad34e302b41/sem/config_rsyslog - wb: [420] 19 bytes
2016-01-28 15:47:15,199 - helpers.py[DEBUG]: Running config-rsyslog using lock (<FileLock using file '/var/lib/cloud/instances/13862411-b73a-4aa1-9735-9ad34e302b41/sem/config_rsyslog'>)
2016-01-28 15:47:15,199 - cc_rsyslog.py[DEBUG]: Skipping module named rsyslog, no 'rsyslog' key in configuration
2016-01-28 15:47:15,199 - util.py[DEBUG]: Writing to /var/lib/cloud/instances/13862411-b73a-4aa1-9735-9ad34e302b41/sem/config_users_groups - wb: [420] 19 bytes
2016-01-28 15:47:15,200 - helpers.py[DEBUG]: Running config-users-groups using lock (<FileLock using file '/var/lib/cloud/instances/13862411-b73a-4aa1-9735-9ad34e302b41/sem/config_users_groups'>)
2016-01-28 15:47:15,200 - importer.py[DEBUG]: Looking for modules ['cloudinit.mergers.m_list'] that have attributes ['Merger']
2016-01-28 15:47:15,200 - importer.py[DEBUG]: Found m_list with attributes ['Merger'] in ['cloudinit.mergers.m_list']
2016-01-28 15:47:15,200 - importer.py[DEBUG]: Looking for modules ['cloudinit.mergers.m_dict'] that have attributes ['Merger']
2016-01-28 15:47:15,200 - importer.py[DEBUG]: Found m_dict with attributes ['Merger'] in ['cloudinit.mergers.m_dict']
2016-01-28 15:47:15,200 - importer.py[DEBUG]: Looking for modules ['cloudinit.mergers.m_str'] that have attributes ['Merger']
2016-01-28 15:47:15,200 - importer.py[DEBUG]: Found m_str with attributes ['Merger'] in ['cloudinit.mergers.m_str']
2016-01-28 15:47:15,200 - __init__.py[DEBUG]: Merging 'dict' into 'dict' using method '_handle_unknown' of 'LookupMerger: (3)'
2016-01-28 15:47:15,200 - __init__.py[DEBUG]: Merging using located merger 'DictMerger: (method=no_replace,recurse_str=False,recurse_dict=True,recurse_array=False,allow_delete=False)' since it had method '_on_dict'
2016-01-28 15:47:15,201 - importer.py[DEBUG]: Looking for modules ['cloudinit.mergers.m_list'] that have attributes ['Merger']
2016-01-28 15:47:15,201 - importer.py[DEBUG]: Found m_list with attributes ['Merger'] in ['cloudinit.mergers.m_list']
2016-01-28 15:47:15,201 - importer.py[DEBUG]: Looking for modules ['cloudinit.mergers.m_dict'] that have attributes ['Merger']
2016-01-28 15:47:15,201 - importer.py[DEBUG]: Found m_dict with attributes ['Merger'] in ['cloudinit.mergers.m_dict']
2016-01-28 15:47:15,201 - importer.py[DEBUG]: Looking for modules ['cloudinit.mergers.m_str'] that have attributes ['Merger']
2016-01-28 15:47:15,201 - importer.py[DEBUG]: Found m_str with attributes ['Merger'] in ['cloudinit.mergers.m_str']
2016-01-28 15:47:15,201 - __init__.py[DEBUG]: Merging 'dict' into 'dict' using method '_handle_unknown' of 'LookupMerger: (3)'
2016-01-28 15:47:15,201 - __init__.py[DEBUG]: Merging using located merger 'DictMerger: (method=no_replace,recurse_str=False,recurse_dict=True,recurse_array=False,allow_delete=False)' since it had method '_on_dict'
2016-01-28 15:47:15,201 - importer.py[DEBUG]: Looking for modules ['cloudinit.mergers.m_list'] that have attributes ['Merger']
2016-01-28 15:47:15,201 - importer.py[DEBUG]: Found m_list with attributes ['Merger'] in ['cloudinit.mergers.m_list']
2016-01-28 15:47:15,201 - importer.py[DEBUG]: Looking for modules ['cloudinit.mergers.m_dict'] that have attributes ['Merger']
2016-01-28 15:47:15,201 - importer.py[DEBUG]: Found m_dict with attributes ['Merger'] in ['cloudinit.mergers.m_dict']
2016-01-28 15:47:15,201 - importer.py[DEBUG]: Looking for modules ['cloudinit.mergers.m_str'] that have attributes ['Merger']
2016-01-28 15:47:15,201 - importer.py[DEBUG]: Found m_str with attributes ['Merger'] in ['cloudinit.mergers.m_str']
2016-01-28 15:47:15,202 - __init__.py[DEBUG]: Merging 'dict' into 'dict' using method '_handle_unknown' of 'LookupMerger: (3)'
2016-01-28 15:47:15,202 - __init__.py[DEBUG]: Merging using located merger 'DictMerger: (method=no_replace,recurse_str=False,recurse_dict=True,recurse_array=False,allow_delete=False)' since it had method '_on_dict'
2016-01-28 15:47:15,202 - __init__.py[DEBUG]: Adding user ubuntu
2016-01-28 15:47:15,202 - util.py[DEBUG]: Running hidden command to protect sensitive input/output logstring: ['useradd', 'ubuntu', '--shell', '/bin/bash', '--comment', 'Ubuntu', '--groups', 'adm,audio,cdrom,dialout,dip,floppy,netdev,plugdev,sudo,video', '-m']
2016-01-28 15:47:15,195 - util.py[DEBUG]: Failed forking and calling callback NoneType
Traceback (most recent call last):
  File "/usr/lib/python2.7/dist-packages/cloudinit/util.py", line 225, in fork_cb
    child_cb(*args)
TypeError: 'NoneType' object is not callable
2016-01-28 15:47:15,311 - util.py[DEBUG]: Running command ['passwd', '-l', 'ubuntu'] with allowed return codes [0] (shell=False, capture=True)
2016-01-28 15:47:15,331 - util.py[DEBUG]: Reading from /etc/sudoers (quiet=False)
2016-01-28 15:47:15,331 - util.py[DEBUG]: Read 745 bytes from /etc/sudoers
2016-01-28 15:47:15,333 - util.py[DEBUG]: Writing to /etc/sudoers.d/90-cloud-init-users - wb: [288] 123 bytes
2016-01-28 15:47:15,334 - util.py[DEBUG]: Writing to /var/lib/cloud/instances/13862411-b73a-4aa1-9735-9ad34e302b41/sem/config_ssh - wb: [420] 20 bytes
2016-01-28 15:47:15,334 - helpers.py[DEBUG]: Running config-ssh using lock (<FileLock using file '/var/lib/cloud/instances/13862411-b73a-4aa1-9735-9ad34e302b41/sem/config_ssh'>)
2016-01-28 15:47:15,335 - util.py[DEBUG]: Running command ['ssh-keygen', '-t', 'rsa', '-N', '', '-f', '/etc/ssh/ssh_host_rsa_key'] with allowed return codes [0] (shell=False, capture=True)
2016-01-28 15:47:15,360 - util.py[DEBUG]: Running command ['ssh-keygen', '-t', 'dsa', '-N', '', '-f', '/etc/ssh/ssh_host_dsa_key'] with allowed return codes [0] (shell=False, capture=True)
2016-01-28 15:47:15,548 - util.py[DEBUG]: Running command ['ssh-keygen', '-t', 'ecdsa', '-N', '', '-f', '/etc/ssh/ssh_host_ecdsa_key'] with allowed return codes [0] (shell=False, capture=True)
2016-01-28 15:47:15,553 - util.py[DEBUG]: Running command ['ssh-keygen', '-t', 'ed25519', '-N', '', '-f', '/etc/ssh/ssh_host_ed25519_key'] with allowed return codes [0] (shell=False, capture=True)
2016-01-28 15:47:15,558 - importer.py[DEBUG]: Looking for modules ['cloudinit.mergers.m_list'] that have attributes ['Merger']
2016-01-28 15:47:15,558 - importer.py[DEBUG]: Found m_list with attributes ['Merger'] in ['cloudinit.mergers.m_list']
2016-01-28 15:47:15,558 - importer.py[DEBUG]: Looking for modules ['cloudinit.mergers.m_dict'] that have attributes ['Merger']
2016-01-28 15:47:15,558 - importer.py[DEBUG]: Found m_dict with attributes ['Merger'] in ['cloudinit.mergers.m_dict']
2016-01-28 15:47:15,558 - importer.py[DEBUG]: Looking for modules ['cloudinit.mergers.m_str'] that have attributes ['Merger']
2016-01-28 15:47:15,558 - importer.py[DEBUG]: Found m_str with attributes ['Merger'] in ['cloudinit.mergers.m_str']
2016-01-28 15:47:15,559 - __init__.py[DEBUG]: Merging 'dict' into 'dict' using method '_handle_unknown' of 'LookupMerger: (3)'
2016-01-28 15:47:15,559 - __init__.py[DEBUG]: Merging using located merger 'DictMerger: (method=no_replace,recurse_str=False,recurse_dict=True,recurse_array=False,allow_delete=False)' since it had method '_on_dict'
2016-01-28 15:47:15,559 - importer.py[DEBUG]: Looking for modules ['cloudinit.mergers.m_list'] that have attributes ['Merger']
2016-01-28 15:47:15,559 - importer.py[DEBUG]: Found m_list with attributes ['Merger'] in ['cloudinit.mergers.m_list']
2016-01-28 15:47:15,559 - importer.py[DEBUG]: Looking for modules ['cloudinit.mergers.m_dict'] that have attributes ['Merger']
2016-01-28 15:47:15,559 - importer.py[DEBUG]: Found m_dict with attributes ['Merger'] in ['cloudinit.mergers.m_dict']
2016-01-28 15:47:15,559 - importer.py[DEBUG]: Looking for modules ['cloudinit.mergers.m_str'] that have attributes ['Merger']
2016-01-28 15:47:15,559 - importer.py[DEBUG]: Found m_str with attributes ['Merger'] in ['cloudinit.mergers.m_str']
2016-01-28 15:47:15,559 - __init__.py[DEBUG]: Merging 'dict' into 'dict' using method '_handle_unknown' of 'LookupMerger: (3)'
2016-01-28 15:47:15,560 - __init__.py[DEBUG]: Merging using located merger 'DictMerger: (method=no_replace,recurse_str=False,recurse_dict=True,recurse_array=False,allow_delete=False)' since it had method '_on_dict'
2016-01-28 15:47:15,560 - importer.py[DEBUG]: Looking for modules ['cloudinit.mergers.m_list'] that have attributes ['Merger']
2016-01-28 15:47:15,560 - importer.py[DEBUG]: Found m_list with attributes ['Merger'] in ['cloudinit.mergers.m_list']
2016-01-28 15:47:15,560 - importer.py[DEBUG]: Looking for modules ['cloudinit.mergers.m_dict'] that have attributes ['Merger']
2016-01-28 15:47:15,560 - importer.py[DEBUG]: Found m_dict with attributes ['Merger'] in ['cloudinit.mergers.m_dict']
2016-01-28 15:47:15,560 - importer.py[DEBUG]: Looking for modules ['cloudinit.mergers.m_str'] that have attributes ['Merger']
2016-01-28 15:47:15,560 - importer.py[DEBUG]: Found m_str with attributes ['Merger'] in ['cloudinit.mergers.m_str']
2016-01-28 15:47:15,560 - __init__.py[DEBUG]: Merging 'dict' into 'dict' using method '_handle_unknown' of 'LookupMerger: (3)'
2016-01-28 15:47:15,560 - __init__.py[DEBUG]: Merging using located merger 'DictMerger: (method=no_replace,recurse_str=False,recurse_dict=True,recurse_array=False,allow_delete=False)' since it had method '_on_dict'
2016-01-28 15:47:15,561 - util.py[DEBUG]: Changing the ownership of /home/ubuntu/.ssh to 1000:1000
2016-01-28 15:47:15,561 - util.py[DEBUG]: Reading from /etc/ssh/sshd_config (quiet=False)
2016-01-28 15:47:15,562 - util.py[DEBUG]: Read 2513 bytes from /etc/ssh/sshd_config
2016-01-28 15:47:15,562 - util.py[DEBUG]: Writing to /home/ubuntu/.ssh/authorized_keys - wb: [384] 399 bytes
2016-01-28 15:47:15,562 - util.py[DEBUG]: Changing the ownership of /home/ubuntu/.ssh/authorized_keys to 1000:1000
2016-01-28 15:47:15,563 - util.py[DEBUG]: Reading from /etc/ssh/sshd_config (quiet=False)
2016-01-28 15:47:15,563 - util.py[DEBUG]: Read 2513 bytes from /etc/ssh/sshd_config
2016-01-28 15:47:15,563 - util.py[DEBUG]: Reading from /root/.ssh/authorized_keys (quiet=False)
2016-01-28 15:47:15,563 - util.py[DEBUG]: Read 453 bytes from /root/.ssh/authorized_keys
2016-01-28 15:47:15,564 - util.py[DEBUG]: Writing to /root/.ssh/authorized_keys - wb: [384] 453 bytes
2016-01-28 15:47:15,564 - util.py[DEBUG]: Changing the ownership of /root/.ssh/authorized_keys to 0:0
2016-01-28 15:47:15,564 - cloud-init[DEBUG]: Ran 13 modules with 0 failures
2016-01-28 15:47:15,564 - util.py[DEBUG]: Reading from /proc/uptime (quiet=False)
2016-01-28 15:47:15,565 - util.py[DEBUG]: Read 12 bytes from /proc/uptime
2016-01-28 15:47:15,565 - util.py[DEBUG]: cloud-init mode 'init' took 0.659 seconds (0.65)
Jan 28 15:47:16 one-click-build-test-1453995898-67 [CLOUDINIT] util.py[DEBUG]: Cloud-init v. 0.7.5 running 'modules:config' at Thu, 28 Jan 2016 15:47:16 +0000. Up 20.42 seconds.
Jan 28 15:47:16 one-click-build-test-1453995898-67 [CLOUDINIT] importer.py[DEBUG]: Looking for modules ['cc_emit_upstart', 'cloudinit.config.cc_emit_upstart'] that have attributes ['handle']
Jan 28 15:47:16 one-click-build-test-1453995898-67 [CLOUDINIT] importer.py[DEBUG]: Failed at attempted import of 'cc_emit_upstart' due to: No module named cc_emit_upstart
Jan 28 15:47:16 one-click-build-test-1453995898-67 [CLOUDINIT] importer.py[DEBUG]: Found cc_emit_upstart with attributes ['handle'] in ['cloudinit.config.cc_emit_upstart']
Jan 28 15:47:16 one-click-build-test-1453995898-67 [CLOUDINIT] importer.py[DEBUG]: Looking for modules ['cc_disk_setup', 'cloudinit.config.cc_disk_setup'] that have attributes ['handle']
Jan 28 15:47:16 one-click-build-test-1453995898-67 [CLOUDINIT] importer.py[DEBUG]: Failed at attempted import of 'cc_disk_setup' due to: No module named cc_disk_setup
Jan 28 15:47:16 one-click-build-test-1453995898-67 [CLOUDINIT] importer.py[DEBUG]: Found cc_disk_setup with attributes ['handle'] in ['cloudinit.config.cc_disk_setup']
Jan 28 15:47:16 one-click-build-test-1453995898-67 [CLOUDINIT] importer.py[DEBUG]: Looking for modules ['cc_mounts', 'cloudinit.config.cc_mounts'] that have attributes ['handle']
Jan 28 15:47:16 one-click-build-test-1453995898-67 [CLOUDINIT] importer.py[DEBUG]: Failed at attempted import of 'cc_mounts' due to: No module named cc_mounts
Jan 28 15:47:16 one-click-build-test-1453995898-67 [CLOUDINIT] importer.py[DEBUG]: Found cc_mounts with attributes ['handle'] in ['cloudinit.config.cc_mounts']
Jan 28 15:47:16 one-click-build-test-1453995898-67 [CLOUDINIT] importer.py[DEBUG]: Looking for modules ['cc_ssh_import_id', 'cloudinit.config.cc_ssh_import_id'] that have attributes ['handle']
Jan 28 15:47:16 one-click-build-test-1453995898-67 [CLOUDINIT] importer.py[DEBUG]: Failed at attempted import of 'cc_ssh_import_id' due to: No module named cc_ssh_import_id
Jan 28 15:47:16 one-click-build-test-1453995898-67 [CLOUDINIT] importer.py[DEBUG]: Found cc_ssh_import_id with attributes ['handle'] in ['cloudinit.config.cc_ssh_import_id']
Jan 28 15:47:16 one-click-build-test-1453995898-67 [CLOUDINIT] importer.py[DEBUG]: Looking for modules ['cc_locale', 'cloudinit.config.cc_locale'] that have attributes ['handle']
Jan 28 15:47:16 one-click-build-test-1453995898-67 [CLOUDINIT] importer.py[DEBUG]: Failed at attempted import of 'cc_locale' due to: No module named cc_locale
Jan 28 15:47:16 one-click-build-test-1453995898-67 [CLOUDINIT] importer.py[DEBUG]: Found cc_locale with attributes ['handle'] in ['cloudinit.config.cc_locale']
Jan 28 15:47:16 one-click-build-test-1453995898-67 [CLOUDINIT] importer.py[DEBUG]: Looking for modules ['cc_set_passwords', 'cloudinit.config.cc_set_passwords'] that have attributes ['handle']
Jan 28 15:47:16 one-click-build-test-1453995898-67 [CLOUDINIT] importer.py[DEBUG]: Failed at attempted import of 'cc_set_passwords' due to: No module named cc_set_passwords
Jan 28 15:47:16 one-click-build-test-1453995898-67 [CLOUDINIT] importer.py[DEBUG]: Found cc_set_passwords with attributes ['handle'] in ['cloudinit.config.cc_set_passwords']
Jan 28 15:47:16 one-click-build-test-1453995898-67 [CLOUDINIT] importer.py[DEBUG]: Looking for modules ['cc_grub_dpkg', 'cloudinit.config.cc_grub_dpkg'] that have attributes ['handle']
Jan 28 15:47:16 one-click-build-test-1453995898-67 [CLOUDINIT] importer.py[DEBUG]: Failed at attempted import of 'cc_grub_dpkg' due to: No module named cc_grub_dpkg
Jan 28 15:47:16 one-click-build-test-1453995898-67 [CLOUDINIT] importer.py[DEBUG]: Found cc_grub_dpkg with attributes ['handle'] in ['cloudinit.config.cc_grub_dpkg']
Jan 28 15:47:16 one-click-build-test-1453995898-67 [CLOUDINIT] importer.py[DEBUG]: Looking for modules ['cc_apt_pipelining', 'cloudinit.config.cc_apt_pipelining'] that have attributes ['handle']
Jan 28 15:47:16 one-click-build-test-1453995898-67 [CLOUDINIT] importer.py[DEBUG]: Failed at attempted import of 'cc_apt_pipelining' due to: No module named cc_apt_pipelining
Jan 28 15:47:16 one-click-build-test-1453995898-67 [CLOUDINIT] importer.py[DEBUG]: Found cc_apt_pipelining with attributes ['handle'] in ['cloudinit.config.cc_apt_pipelining']
Jan 28 15:47:16 one-click-build-test-1453995898-67 [CLOUDINIT] importer.py[DEBUG]: Looking for modules ['cc_apt_configure', 'cloudinit.config.cc_apt_configure'] that have attributes ['handle']
Jan 28 15:47:16 one-click-build-test-1453995898-67 [CLOUDINIT] importer.py[DEBUG]: Failed at attempted import of 'cc_apt_configure' due to: No module named cc_apt_configure
Jan 28 15:47:16 one-click-build-test-1453995898-67 [CLOUDINIT] importer.py[DEBUG]: Found cc_apt_configure with attributes ['handle'] in ['cloudinit.config.cc_apt_configure']
Jan 28 15:47:16 one-click-build-test-1453995898-67 [CLOUDINIT] importer.py[DEBUG]: Looking for modules ['cc_package_update_upgrade_install', 'cloudinit.config.cc_package_update_upgrade_install'] that have attributes ['handle']
Jan 28 15:47:16 one-click-build-test-1453995898-67 [CLOUDINIT] importer.py[DEBUG]: Failed at attempted import of 'cc_package_update_upgrade_install' due to: No module named cc_package_update_upgrade_install
Jan 28 15:47:16 one-click-build-test-1453995898-67 [CLOUDINIT] importer.py[DEBUG]: Found cc_package_update_upgrade_install with attributes ['handle'] in ['cloudinit.config.cc_package_update_upgrade_install']
Jan 28 15:47:16 one-click-build-test-1453995898-67 [CLOUDINIT] importer.py[DEBUG]: Looking for modules ['cc_landscape', 'cloudinit.config.cc_landscape'] that have attributes ['handle']
Jan 28 15:47:16 one-click-build-test-1453995898-67 [CLOUDINIT] importer.py[DEBUG]: Failed at attempted import of 'cc_landscape' due to: No module named cc_landscape
Jan 28 15:47:16 one-click-build-test-1453995898-67 [CLOUDINIT] importer.py[DEBUG]: Found cc_landscape with attributes ['handle'] in ['cloudinit.config.cc_landscape']
Jan 28 15:47:16 one-click-build-test-1453995898-67 [CLOUDINIT] importer.py[DEBUG]: Looking for modules ['cc_timezone', 'cloudinit.config.cc_timezone'] that have attributes ['handle']
Jan 28 15:47:16 one-click-build-test-1453995898-67 [CLOUDINIT] importer.py[DEBUG]: Failed at attempted import of 'cc_timezone' due to: No module named cc_timezone
Jan 28 15:47:16 one-click-build-test-1453995898-67 [CLOUDINIT] importer.py[DEBUG]: Found cc_timezone with attributes ['handle'] in ['cloudinit.config.cc_timezone']
Jan 28 15:47:16 one-click-build-test-1453995898-67 [CLOUDINIT] importer.py[DEBUG]: Looking for modules ['cc_puppet', 'cloudinit.config.cc_puppet'] that have attributes ['handle']
Jan 28 15:47:16 one-click-build-test-1453995898-67 [CLOUDINIT] importer.py[DEBUG]: Failed at attempted import of 'cc_puppet' due to: No module named cc_puppet
Jan 28 15:47:16 one-click-build-test-1453995898-67 [CLOUDINIT] importer.py[DEBUG]: Found cc_puppet with attributes ['handle'] in ['cloudinit.config.cc_puppet']
Jan 28 15:47:16 one-click-build-test-1453995898-67 [CLOUDINIT] importer.py[DEBUG]: Looking for modules ['cc_chef', 'cloudinit.config.cc_chef'] that have attributes ['handle']
Jan 28 15:47:16 one-click-build-test-1453995898-67 [CLOUDINIT] importer.py[DEBUG]: Failed at attempted import of 'cc_chef' due to: No module named cc_chef
Jan 28 15:47:16 one-click-build-test-1453995898-67 [CLOUDINIT] importer.py[DEBUG]: Found cc_chef with attributes ['handle'] in ['cloudinit.config.cc_chef']
Jan 28 15:47:16 one-click-build-test-1453995898-67 [CLOUDINIT] importer.py[DEBUG]: Looking for modules ['cc_salt_minion', 'cloudinit.config.cc_salt_minion'] that have attributes ['handle']
Jan 28 15:47:16 one-click-build-test-1453995898-67 [CLOUDINIT] importer.py[DEBUG]: Failed at attempted import of 'cc_salt_minion' due to: No module named cc_salt_minion
Jan 28 15:47:16 one-click-build-test-1453995898-67 [CLOUDINIT] importer.py[DEBUG]: Found cc_salt_minion with attributes ['handle'] in ['cloudinit.config.cc_salt_minion']
Jan 28 15:47:16 one-click-build-test-1453995898-67 [CLOUDINIT] importer.py[DEBUG]: Looking for modules ['cc_mcollective', 'cloudinit.config.cc_mcollective'] that have attributes ['handle']
Jan 28 15:47:16 one-click-build-test-1453995898-67 [CLOUDINIT] importer.py[DEBUG]: Failed at attempted import of 'cc_mcollective' due to: No module named cc_mcollective
Jan 28 15:47:16 one-click-build-test-1453995898-67 [CLOUDINIT] importer.py[DEBUG]: Found cc_mcollective with attributes ['handle'] in ['cloudinit.config.cc_mcollective']
Jan 28 15:47:16 one-click-build-test-1453995898-67 [CLOUDINIT] importer.py[DEBUG]: Looking for modules ['cc_disable_ec2_metadata', 'cloudinit.config.cc_disable_ec2_metadata'] that have attributes ['handle']
Jan 28 15:47:16 one-click-build-test-1453995898-67 [CLOUDINIT] importer.py[DEBUG]: Failed at attempted import of 'cc_disable_ec2_metadata' due to: No module named cc_disable_ec2_metadata
Jan 28 15:47:16 one-click-build-test-1453995898-67 [CLOUDINIT] importer.py[DEBUG]: Found cc_disable_ec2_metadata with attributes ['handle'] in ['cloudinit.config.cc_disable_ec2_metadata']
Jan 28 15:47:16 one-click-build-test-1453995898-67 [CLOUDINIT] importer.py[DEBUG]: Looking for modules ['cc_runcmd', 'cloudinit.config.cc_runcmd'] that have attributes ['handle']
Jan 28 15:47:16 one-click-build-test-1453995898-67 [CLOUDINIT] importer.py[DEBUG]: Failed at attempted import of 'cc_runcmd' due to: No module named cc_runcmd
Jan 28 15:47:16 one-click-build-test-1453995898-67 [CLOUDINIT] importer.py[DEBUG]: Found cc_runcmd with attributes ['handle'] in ['cloudinit.config.cc_runcmd']
Jan 28 15:47:16 one-click-build-test-1453995898-67 [CLOUDINIT] importer.py[DEBUG]: Looking for modules ['cc_byobu', 'cloudinit.config.cc_byobu'] that have attributes ['handle']
Jan 28 15:47:16 one-click-build-test-1453995898-67 [CLOUDINIT] importer.py[DEBUG]: Failed at attempted import of 'cc_byobu' due to: No module named cc_byobu
Jan 28 15:47:16 one-click-build-test-1453995898-67 [CLOUDINIT] importer.py[DEBUG]: Found cc_byobu with attributes ['handle'] in ['cloudinit.config.cc_byobu']
Jan 28 15:47:16 one-click-build-test-1453995898-67 [CLOUDINIT] importer.py[DEBUG]: Looking for modules ['ubuntu', 'cloudinit.distros.ubuntu'] that have attributes ['Distro']
Jan 28 15:47:16 one-click-build-test-1453995898-67 [CLOUDINIT] importer.py[DEBUG]: Failed at attempted import of 'ubuntu' due to: No module named ubuntu
Jan 28 15:47:16 one-click-build-test-1453995898-67 [CLOUDINIT] importer.py[DEBUG]: Found ubuntu with attributes ['Distro'] in ['cloudinit.distros.ubuntu']
Jan 28 15:47:16 one-click-build-test-1453995898-67 [CLOUDINIT] stages.py[DEBUG]: Using distro class <class 'cloudinit.distros.ubuntu.Distro'>
Jan 28 15:47:16 one-click-build-test-1453995898-67 [CLOUDINIT] helpers.py[DEBUG]: Running config-emit_upstart using lock (<cloudinit.helpers.DummyLock object at 0x7f1c9ae78d10>)
Jan 28 15:47:16 one-click-build-test-1453995898-67 [CLOUDINIT] util.py[DEBUG]: Running command ['initctl', 'emit', 'cloud-config', 'CLOUD_CFG=/var/lib/cloud/instance/cloud-config.txt'] with allowed return codes [0] (shell=False, capture=True)
Jan 28 15:47:16 one-click-build-test-1453995898-67 [CLOUDINIT] util.py[DEBUG]: Writing to /var/lib/cloud/instances/13862411-b73a-4aa1-9735-9ad34e302b41/sem/config_disk_setup - wb: [420] 20 bytes
Jan 28 15:47:16 one-click-build-test-1453995898-67 [CLOUDINIT] helpers.py[DEBUG]: Running config-disk_setup using lock (<FileLock using file '/var/lib/cloud/instances/13862411-b73a-4aa1-9735-9ad34e302b41/sem/config_disk_setup'>)
Jan 28 15:47:16 one-click-build-test-1453995898-67 [CLOUDINIT] util.py[DEBUG]: Writing to /var/lib/cloud/instances/13862411-b73a-4aa1-9735-9ad34e302b41/sem/config_mounts - wb: [420] 20 bytes
Jan 28 15:47:16 one-click-build-test-1453995898-67 [CLOUDINIT] helpers.py[DEBUG]: Running config-mounts using lock (<FileLock using file '/var/lib/cloud/instances/13862411-b73a-4aa1-9735-9ad34e302b41/sem/config_mounts'>)
Jan 28 15:47:16 one-click-build-test-1453995898-67 [CLOUDINIT] cc_mounts.py[DEBUG]: Attempting to determine the real name of ephemeral0
Jan 28 15:47:16 one-click-build-test-1453995898-67 [CLOUDINIT] openstack.py[DEBUG]: Using ec2 style lookup to find device ['ephemeral0']
Jan 28 15:47:16 one-click-build-test-1453995898-67 [CLOUDINIT] openstack.py[DEBUG]: Using openstack style lookup to find device ['ephemeral0']
Jan 28 15:47:16 one-click-build-test-1453995898-67 [CLOUDINIT] util.py[DEBUG]: Running command ['blkid', '-tLABEL=ephemeral0', '-odevice'] with allowed return codes [0, 2] (shell=False, capture=True)
Jan 28 15:47:16 one-click-build-test-1453995898-67 [CLOUDINIT] cc_mounts.py[DEBUG]: Ignoring nonexistant default named mount ephemeral0
Jan 28 15:47:16 one-click-build-test-1453995898-67 [CLOUDINIT] cc_mounts.py[DEBUG]: Attempting to determine the real name of swap
Jan 28 15:47:16 one-click-build-test-1453995898-67 [CLOUDINIT] openstack.py[DEBUG]: Using ec2 style lookup to find device ['swap']
Jan 28 15:47:16 one-click-build-test-1453995898-67 [CLOUDINIT] openstack.py[DEBUG]: Using openstack style lookup to find device ['swap']
Jan 28 15:47:16 one-click-build-test-1453995898-67 [CLOUDINIT] util.py[DEBUG]: Running command ['blkid', '-tTYPE=swap', '-odevice'] with allowed return codes [0, 2] (shell=False, capture=True)
Jan 28 15:47:16 one-click-build-test-1453995898-67 [CLOUDINIT] cc_mounts.py[DEBUG]: Ignoring nonexistant default named mount swap
Jan 28 15:47:16 one-click-build-test-1453995898-67 [CLOUDINIT] cc_mounts.py[DEBUG]: No modifications to fstab needed.
Jan 28 15:47:16 one-click-build-test-1453995898-67 [CLOUDINIT] util.py[DEBUG]: Writing to /var/lib/cloud/instances/13862411-b73a-4aa1-9735-9ad34e302b41/sem/config_ssh_import_id - wb: [420] 20 bytes
Jan 28 15:47:16 one-click-build-test-1453995898-67 [CLOUDINIT] helpers.py[DEBUG]: Running config-ssh-import-id using lock (<FileLock using file '/var/lib/cloud/instances/13862411-b73a-4aa1-9735-9ad34e302b41/sem/config_ssh_import_id'>)
Jan 28 15:47:16 one-click-build-test-1453995898-67 [CLOUDINIT] importer.py[DEBUG]: Looking for modules ['cloudinit.mergers.m_list'] that have attributes ['Merger']
Jan 28 15:47:16 one-click-build-test-1453995898-67 [CLOUDINIT] importer.py[DEBUG]: Found m_list with attributes ['Merger'] in ['cloudinit.mergers.m_list']
Jan 28 15:47:16 one-click-build-test-1453995898-67 [CLOUDINIT] importer.py[DEBUG]: Looking for modules ['cloudinit.mergers.m_dict'] that have attributes ['Merger']
Jan 28 15:47:16 one-click-build-test-1453995898-67 [CLOUDINIT] importer.py[DEBUG]: Found m_dict with attributes ['Merger'] in ['cloudinit.mergers.m_dict']
Jan 28 15:47:16 one-click-build-test-1453995898-67 [CLOUDINIT] importer.py[DEBUG]: Looking for modules ['cloudinit.mergers.m_str'] that have attributes ['Merger']
Jan 28 15:47:16 one-click-build-test-1453995898-67 [CLOUDINIT] importer.py[DEBUG]: Found m_str with attributes ['Merger'] in ['cloudinit.mergers.m_str']
Jan 28 15:47:16 one-click-build-test-1453995898-67 [CLOUDINIT] __init__.py[DEBUG]: Merging 'dict' into 'dict' using method '_handle_unknown' of 'LookupMerger: (3)'
Jan 28 15:47:16 one-click-build-test-1453995898-67 [CLOUDINIT] __init__.py[DEBUG]: Merging using located merger 'DictMerger: (method=no_replace,recurse_str=False,recurse_dict=True,recurse_array=False,allow_delete=False)' since it had method '_on_dict'
Jan 28 15:47:16 one-click-build-test-1453995898-67 [CLOUDINIT] importer.py[DEBUG]: Looking for modules ['cloudinit.mergers.m_list'] that have attributes ['Merger']
Jan 28 15:47:16 one-click-build-test-1453995898-67 [CLOUDINIT] importer.py[DEBUG]: Found m_list with attributes ['Merger'] in ['cloudinit.mergers.m_list']
Jan 28 15:47:16 one-click-build-test-1453995898-67 [CLOUDINIT] importer.py[DEBUG]: Looking for modules ['cloudinit.mergers.m_dict'] that have attributes ['Merger']
Jan 28 15:47:16 one-click-build-test-1453995898-67 [CLOUDINIT] importer.py[DEBUG]: Found m_dict with attributes ['Merger'] in ['cloudinit.mergers.m_dict']
Jan 28 15:47:16 one-click-build-test-1453995898-67 [CLOUDINIT] importer.py[DEBUG]: Looking for modules ['cloudinit.mergers.m_str'] that have attributes ['Merger']
Jan 28 15:47:16 one-click-build-test-1453995898-67 [CLOUDINIT] importer.py[DEBUG]: Found m_str with attributes ['Merger'] in ['cloudinit.mergers.m_str']
Jan 28 15:47:16 one-click-build-test-1453995898-67 [CLOUDINIT] __init__.py[DEBUG]: Merging 'dict' into 'dict' using method '_handle_unknown' of 'LookupMerger: (3)'
Jan 28 15:47:16 one-click-build-test-1453995898-67 [CLOUDINIT] __init__.py[DEBUG]: Merging using located merger 'DictMerger: (method=no_replace,recurse_str=False,recurse_dict=True,recurse_array=False,allow_delete=False)' since it had method '_on_dict'
Jan 28 15:47:16 one-click-build-test-1453995898-67 [CLOUDINIT] importer.py[DEBUG]: Looking for modules ['cloudinit.mergers.m_list'] that have attributes ['Merger']
Jan 28 15:47:16 one-click-build-test-1453995898-67 [CLOUDINIT] importer.py[DEBUG]: Found m_list with attributes ['Merger'] in ['cloudinit.mergers.m_list']
Jan 28 15:47:16 one-click-build-test-1453995898-67 [CLOUDINIT] importer.py[DEBUG]: Looking for modules ['cloudinit.mergers.m_dict'] that have attributes ['Merger']
Jan 28 15:47:16 one-click-build-test-1453995898-67 [CLOUDINIT] importer.py[DEBUG]: Found m_dict with attributes ['Merger'] in ['cloudinit.mergers.m_dict']
Jan 28 15:47:16 one-click-build-test-1453995898-67 [CLOUDINIT] importer.py[DEBUG]: Looking for modules ['cloudinit.mergers.m_str'] that have attributes ['Merger']
Jan 28 15:47:16 one-click-build-test-1453995898-67 [CLOUDINIT] importer.py[DEBUG]: Found m_str with attributes ['Merger'] in ['cloudinit.mergers.m_str']
Jan 28 15:47:16 one-click-build-test-1453995898-67 [CLOUDINIT] __init__.py[DEBUG]: Merging 'dict' into 'dict' using method '_handle_unknown' of 'LookupMerger: (3)'
Jan 28 15:47:16 one-click-build-test-1453995898-67 [CLOUDINIT] __init__.py[DEBUG]: Merging using located merger 'DictMerger: (method=no_replace,recurse_str=False,recurse_dict=True,recurse_array=False,allow_delete=False)' since it had method '_on_dict'
Jan 28 15:47:16 one-click-build-test-1453995898-67 [CLOUDINIT] util.py[DEBUG]: Writing to /var/lib/cloud/instances/13862411-b73a-4aa1-9735-9ad34e302b41/sem/config_locale - wb: [420] 19 bytes
Jan 28 15:47:16 one-click-build-test-1453995898-67 [CLOUDINIT] helpers.py[DEBUG]: Running config-locale using lock (<FileLock using file '/var/lib/cloud/instances/13862411-b73a-4aa1-9735-9ad34e302b41/sem/config_locale'>)
Jan 28 15:47:16 one-click-build-test-1453995898-67 [CLOUDINIT] cc_locale.py[DEBUG]: Setting locale to en_US.UTF-8
Jan 28 15:47:16 one-click-build-test-1453995898-67 [CLOUDINIT] util.py[DEBUG]: Running command ['locale-gen', 'en_US.UTF-8'] with allowed return codes [0] (shell=False, capture=False)
Jan 28 15:47:17 one-click-build-test-1453995898-67 [CLOUDINIT] util.py[DEBUG]: Running command ['update-locale', 'en_US.UTF-8'] with allowed return codes [0] (shell=False, capture=False)
Jan 28 15:47:17 one-click-build-test-1453995898-67 [CLOUDINIT] util.py[DEBUG]: Writing to /etc/default/locale - wb: [420] 87 bytes
Jan 28 15:47:17 one-click-build-test-1453995898-67 [CLOUDINIT] util.py[DEBUG]: Writing to /var/lib/cloud/instances/13862411-b73a-4aa1-9735-9ad34e302b41/sem/config_set_passwords - wb: [420] 20 bytes
Jan 28 15:47:17 one-click-build-test-1453995898-67 [CLOUDINIT] helpers.py[DEBUG]: Running config-set-passwords using lock (<FileLock using file '/var/lib/cloud/instances/13862411-b73a-4aa1-9735-9ad34e302b41/sem/config_set_passwords'>)
Jan 28 15:47:17 one-click-build-test-1453995898-67 [CLOUDINIT] util.py[DEBUG]: Reading from /etc/ssh/sshd_config (quiet=False)
Jan 28 15:47:17 one-click-build-test-1453995898-67 [CLOUDINIT] util.py[DEBUG]: Read 2513 bytes from /etc/ssh/sshd_config
Jan 28 15:47:17 one-click-build-test-1453995898-67 [CLOUDINIT] cc_set_passwords.py[DEBUG]: Adding new auth line 88
Jan 28 15:47:17 one-click-build-test-1453995898-67 [CLOUDINIT] util.py[DEBUG]: Writing to /etc/ssh/sshd_config - wb: [420] 2539 bytes
Jan 28 15:47:17 one-click-build-test-1453995898-67 [CLOUDINIT] util.py[DEBUG]: Running command ['service', 'ssh', 'restart'] with allowed return codes [0] (shell=False, capture=True)
Jan 28 15:47:17 one-click-build-test-1453995898-67 [CLOUDINIT] cc_set_passwords.py[DEBUG]: Restarted the ssh daemon
Jan 28 15:47:17 one-click-build-test-1453995898-67 [CLOUDINIT] util.py[DEBUG]: Writing to /var/lib/cloud/instances/13862411-b73a-4aa1-9735-9ad34e302b41/sem/config_grub_dpkg - wb: [420] 20 bytes
Jan 28 15:47:17 one-click-build-test-1453995898-67 [CLOUDINIT] helpers.py[DEBUG]: Running config-grub-dpkg using lock (<FileLock using file '/var/lib/cloud/instances/13862411-b73a-4aa1-9735-9ad34e302b41/sem/config_grub_dpkg'>)
Jan 28 15:47:17 one-click-build-test-1453995898-67 [CLOUDINIT] cc_grub_dpkg.py[DEBUG]: Setting grub debconf-set-selections with '/dev/xvda','false'
Jan 28 15:47:17 one-click-build-test-1453995898-67 [CLOUDINIT] util.py[DEBUG]: Running command ['debconf-set-selections'] with allowed return codes [0] (shell=False, capture=True)
Jan 28 15:47:17 one-click-build-test-1453995898-67 [CLOUDINIT] util.py[WARNING]: Failed to run debconf-set-selections for grub-dpkg
Jan 28 15:47:17 one-click-build-test-1453995898-67 [CLOUDINIT] util.py[DEBUG]: Failed to run debconf-set-selections for grub-dpkg#012Traceback (most recent call last):#012  File "/usr/lib/python2.7/dist-packages/cloudinit/config/cc_grub_dpkg.py", line 66, in handle#012    util.subp(['debconf-set-selections'], dconf_sel)#012  File "/usr/lib/python2.7/dist-packages/cloudinit/util.py", line 1564, in subp#012    cmd=args)#012ProcessExecutionError: Unexpected error while running command.#012Command: ['debconf-set-selections']#012Exit code: 1#012Reason: -#012Stdout: ''#012Stderr: 'debconf: DbDriver "config": /var/cache/debconf/config.dat is locked by another process: Resource temporarily unavailable\n'
Jan 28 15:47:17 one-click-build-test-1453995898-67 [CLOUDINIT] util.py[DEBUG]: Writing to /var/lib/cloud/instances/13862411-b73a-4aa1-9735-9ad34e302b41/sem/config_apt_pipelining - wb: [420] 19 bytes
Jan 28 15:47:17 one-click-build-test-1453995898-67 [CLOUDINIT] helpers.py[DEBUG]: Running config-apt-pipelining using lock (<FileLock using file '/var/lib/cloud/instances/13862411-b73a-4aa1-9735-9ad34e302b41/sem/config_apt_pipelining'>)
Jan 28 15:47:17 one-click-build-test-1453995898-67 [CLOUDINIT] util.py[DEBUG]: Writing to /etc/apt/apt.conf.d/90cloud-init-pipelining - wb: [420] 80 bytes
Jan 28 15:47:17 one-click-build-test-1453995898-67 [CLOUDINIT] cc_apt_pipelining.py[DEBUG]: Wrote /etc/apt/apt.conf.d/90cloud-init-pipelining with apt pipeline depth setting 0
Jan 28 15:47:17 one-click-build-test-1453995898-67 [CLOUDINIT] util.py[DEBUG]: Writing to /var/lib/cloud/instances/13862411-b73a-4aa1-9735-9ad34e302b41/sem/config_apt_configure - wb: [420] 20 bytes
Jan 28 15:47:17 one-click-build-test-1453995898-67 [CLOUDINIT] helpers.py[DEBUG]: Running config-apt-configure using lock (<FileLock using file '/var/lib/cloud/instances/13862411-b73a-4aa1-9735-9ad34e302b41/sem/config_apt_configure'>)
Jan 28 15:47:17 one-click-build-test-1453995898-67 [CLOUDINIT] util.py[DEBUG]: Running command ['lsb_release', '-cs'] with allowed return codes [0] (shell=False, capture=True)
Jan 28 15:47:17 one-click-build-test-1453995898-67 [CLOUDINIT] util.py[DEBUG]: Running command ['dpkg', '--print-architecture'] with allowed return codes [0] (shell=False, capture=True)
Jan 28 15:47:17 one-click-build-test-1453995898-67 [CLOUDINIT] __init__.py[DEBUG]: filtered distro mirror info: {'security': 'http://security.ubuntu.com/ubuntu', 'primary': u'http://nova.clouds.archive.ubuntu.com/ubuntu/'}
Jan 28 15:47:17 one-click-build-test-1453995898-67 [CLOUDINIT] cc_apt_configure.py[DEBUG]: Mirror info: {'security': 'http://security.ubuntu.com/ubuntu', 'primary': u'http://nova.clouds.archive.ubuntu.com/ubuntu/', 'mirror': u'http://nova.clouds.archive.ubuntu.com/ubuntu/'}
Jan 28 15:47:17 one-click-build-test-1453995898-67 [CLOUDINIT] util.py[DEBUG]: Writing to /var/lib/cloud/instances/13862411-b73a-4aa1-9735-9ad34e302b41/sem/config_package_update_upgrade_install - wb: [420] 20 bytes
Jan 28 15:47:17 one-click-build-test-1453995898-67 [CLOUDINIT] helpers.py[DEBUG]: Running config-package-update-upgrade-install using lock (<FileLock using file '/var/lib/cloud/instances/13862411-b73a-4aa1-9735-9ad34e302b41/sem/config_package_update_upgrade_install'>)
Jan 28 15:47:17 one-click-build-test-1453995898-67 [CLOUDINIT] util.py[DEBUG]: Writing to /var/lib/cloud/instances/13862411-b73a-4aa1-9735-9ad34e302b41/sem/config_landscape - wb: [420] 20 bytes
Jan 28 15:47:17 one-click-build-test-1453995898-67 [CLOUDINIT] helpers.py[DEBUG]: Running config-landscape using lock (<FileLock using file '/var/lib/cloud/instances/13862411-b73a-4aa1-9735-9ad34e302b41/sem/config_landscape'>)
Jan 28 15:47:17 one-click-build-test-1453995898-67 [CLOUDINIT] util.py[DEBUG]: Writing to /var/lib/cloud/instances/13862411-b73a-4aa1-9735-9ad34e302b41/sem/config_timezone - wb: [420] 20 bytes
Jan 28 15:47:17 one-click-build-test-1453995898-67 [CLOUDINIT] helpers.py[DEBUG]: Running config-timezone using lock (<FileLock using file '/var/lib/cloud/instances/13862411-b73a-4aa1-9735-9ad34e302b41/sem/config_timezone'>)
Jan 28 15:47:17 one-click-build-test-1453995898-67 [CLOUDINIT] cc_timezone.py[DEBUG]: Skipping module named timezone, no 'timezone' specified
Jan 28 15:47:17 one-click-build-test-1453995898-67 [CLOUDINIT] util.py[DEBUG]: Writing to /var/lib/cloud/instances/13862411-b73a-4aa1-9735-9ad34e302b41/sem/config_puppet - wb: [420] 20 bytes
Jan 28 15:47:17 one-click-build-test-1453995898-67 [CLOUDINIT] helpers.py[DEBUG]: Running config-puppet using lock (<FileLock using file '/var/lib/cloud/instances/13862411-b73a-4aa1-9735-9ad34e302b41/sem/config_puppet'>)
Jan 28 15:47:17 one-click-build-test-1453995898-67 [CLOUDINIT] cc_puppet.py[DEBUG]: Skipping module named puppet, no 'puppet' configuration found
Jan 28 15:47:17 one-click-build-test-1453995898-67 [CLOUDINIT] util.py[DEBUG]: Writing to /var/lib/cloud/instances/13862411-b73a-4aa1-9735-9ad34e302b41/sem/config_chef - wb: [420] 20 bytes
Jan 28 15:47:17 one-click-build-test-1453995898-67 [CLOUDINIT] helpers.py[DEBUG]: Running config-chef using lock (<FileLock using file '/var/lib/cloud/instances/13862411-b73a-4aa1-9735-9ad34e302b41/sem/config_chef'>)
Jan 28 15:47:17 one-click-build-test-1453995898-67 [CLOUDINIT] cc_chef.py[DEBUG]: Skipping module named chef, no 'chef' key in configuration
Jan 28 15:47:17 one-click-build-test-1453995898-67 [CLOUDINIT] util.py[DEBUG]: Writing to /var/lib/cloud/instances/13862411-b73a-4aa1-9735-9ad34e302b41/sem/config_salt_minion - wb: [420] 20 bytes
Jan 28 15:47:17 one-click-build-test-1453995898-67 [CLOUDINIT] helpers.py[DEBUG]: Running config-salt-minion using lock (<FileLock using file '/var/lib/cloud/instances/13862411-b73a-4aa1-9735-9ad34e302b41/sem/config_salt_minion'>)
Jan 28 15:47:17 one-click-build-test-1453995898-67 [CLOUDINIT] cc_salt_minion.py[DEBUG]: Skipping module named salt-minion, no 'salt_minion' key in configuration
Jan 28 15:47:17 one-click-build-test-1453995898-67 [CLOUDINIT] util.py[DEBUG]: Writing to /var/lib/cloud/instances/13862411-b73a-4aa1-9735-9ad34e302b41/sem/config_mcollective - wb: [420] 20 bytes
Jan 28 15:47:17 one-click-build-test-1453995898-67 [CLOUDINIT] helpers.py[DEBUG]: Running config-mcollective using lock (<FileLock using file '/var/lib/cloud/instances/13862411-b73a-4aa1-9735-9ad34e302b41/sem/config_mcollective'>)
Jan 28 15:47:17 one-click-build-test-1453995898-67 [CLOUDINIT] cc_mcollective.py[DEBUG]: Skipping module named mcollective, no 'mcollective' key in configuration
Jan 28 15:47:17 one-click-build-test-1453995898-67 [CLOUDINIT] helpers.py[DEBUG]: Running config-disable-ec2-metadata using lock (<cloudinit.helpers.DummyLock object at 0x7f1c9ae3dd50>)
Jan 28 15:47:17 one-click-build-test-1453995898-67 [CLOUDINIT] cc_disable_ec2_metadata.py[DEBUG]: Skipping module named disable-ec2-metadata, disabling the ec2 route not enabled
Jan 28 15:47:17 one-click-build-test-1453995898-67 [CLOUDINIT] util.py[DEBUG]: Writing to /var/lib/cloud/instances/13862411-b73a-4aa1-9735-9ad34e302b41/sem/config_runcmd - wb: [420] 20 bytes
Jan 28 15:47:17 one-click-build-test-1453995898-67 [CLOUDINIT] helpers.py[DEBUG]: Running config-runcmd using lock (<FileLock using file '/var/lib/cloud/instances/13862411-b73a-4aa1-9735-9ad34e302b41/sem/config_runcmd'>)
Jan 28 15:47:17 one-click-build-test-1453995898-67 [CLOUDINIT] cc_runcmd.py[DEBUG]: Skipping module named runcmd, no 'runcmd' key in configuration
Jan 28 15:47:17 one-click-build-test-1453995898-67 [CLOUDINIT] util.py[DEBUG]: Writing to /var/lib/cloud/instances/13862411-b73a-4aa1-9735-9ad34e302b41/sem/config_byobu - wb: [420] 20 bytes
Jan 28 15:47:17 one-click-build-test-1453995898-67 [CLOUDINIT] helpers.py[DEBUG]: Running config-byobu using lock (<FileLock using file '/var/lib/cloud/instances/13862411-b73a-4aa1-9735-9ad34e302b41/sem/config_byobu'>)
Jan 28 15:47:17 one-click-build-test-1453995898-67 [CLOUDINIT] cc_byobu.py[DEBUG]: Skipping module named byobu, no 'byobu' values found
Jan 28 15:47:17 one-click-build-test-1453995898-67 [CLOUDINIT] cloud-init[DEBUG]: Ran 19 modules with 0 failures
Jan 28 15:47:17 one-click-build-test-1453995898-67 [CLOUDINIT] util.py[DEBUG]: Reading from /proc/uptime (quiet=False)
Jan 28 15:47:17 one-click-build-test-1453995898-67 [CLOUDINIT] util.py[DEBUG]: Read 12 bytes from /proc/uptime
Jan 28 15:47:17 one-click-build-test-1453995898-67 [CLOUDINIT] util.py[DEBUG]: cloud-init mode 'modules' took 1.769 seconds (1.77)
Jan 28 15:47:18 one-click-build-test-1453995898-67 [CLOUDINIT] util.py[DEBUG]: Cloud-init v. 0.7.5 running 'modules:final' at Thu, 28 Jan 2016 15:47:18 +0000. Up 23.08 seconds.
Jan 28 15:47:18 one-click-build-test-1453995898-67 [CLOUDINIT] importer.py[DEBUG]: Looking for modules ['cc_rightscale_userdata', 'cloudinit.config.cc_rightscale_userdata'] that have attributes ['handle']
Jan 28 15:47:18 one-click-build-test-1453995898-67 [CLOUDINIT] importer.py[DEBUG]: Failed at attempted import of 'cc_rightscale_userdata' due to: No module named cc_rightscale_userdata
Jan 28 15:47:18 one-click-build-test-1453995898-67 [CLOUDINIT] importer.py[DEBUG]: Found cc_rightscale_userdata with attributes ['handle'] in ['cloudinit.config.cc_rightscale_userdata']
Jan 28 15:47:18 one-click-build-test-1453995898-67 [CLOUDINIT] importer.py[DEBUG]: Looking for modules ['cc_scripts_vendor', 'cloudinit.config.cc_scripts_vendor'] that have attributes ['handle']
Jan 28 15:47:18 one-click-build-test-1453995898-67 [CLOUDINIT] importer.py[DEBUG]: Failed at attempted import of 'cc_scripts_vendor' due to: No module named cc_scripts_vendor
Jan 28 15:47:18 one-click-build-test-1453995898-67 [CLOUDINIT] importer.py[DEBUG]: Found cc_scripts_vendor with attributes ['handle'] in ['cloudinit.config.cc_scripts_vendor']
Jan 28 15:47:18 one-click-build-test-1453995898-67 [CLOUDINIT] importer.py[DEBUG]: Looking for modules ['cc_scripts_per_once', 'cloudinit.config.cc_scripts_per_once'] that have attributes ['handle']
Jan 28 15:47:18 one-click-build-test-1453995898-67 [CLOUDINIT] importer.py[DEBUG]: Failed at attempted import of 'cc_scripts_per_once' due to: No module named cc_scripts_per_once
Jan 28 15:47:18 one-click-build-test-1453995898-67 [CLOUDINIT] importer.py[DEBUG]: Found cc_scripts_per_once with attributes ['handle'] in ['cloudinit.config.cc_scripts_per_once']
Jan 28 15:47:18 one-click-build-test-1453995898-67 [CLOUDINIT] importer.py[DEBUG]: Looking for modules ['cc_scripts_per_boot', 'cloudinit.config.cc_scripts_per_boot'] that have attributes ['handle']
Jan 28 15:47:18 one-click-build-test-1453995898-67 [CLOUDINIT] importer.py[DEBUG]: Failed at attempted import of 'cc_scripts_per_boot' due to: No module named cc_scripts_per_boot
Jan 28 15:47:18 one-click-build-test-1453995898-67 [CLOUDINIT] importer.py[DEBUG]: Found cc_scripts_per_boot with attributes ['handle'] in ['cloudinit.config.cc_scripts_per_boot']
Jan 28 15:47:18 one-click-build-test-1453995898-67 [CLOUDINIT] importer.py[DEBUG]: Looking for modules ['cc_scripts_per_instance', 'cloudinit.config.cc_scripts_per_instance'] that have attributes ['handle']
Jan 28 15:47:18 one-click-build-test-1453995898-67 [CLOUDINIT] importer.py[DEBUG]: Failed at attempted import of 'cc_scripts_per_instance' due to: No module named cc_scripts_per_instance
Jan 28 15:47:18 one-click-build-test-1453995898-67 [CLOUDINIT] importer.py[DEBUG]: Found cc_scripts_per_instance with attributes ['handle'] in ['cloudinit.config.cc_scripts_per_instance']
Jan 28 15:47:18 one-click-build-test-1453995898-67 [CLOUDINIT] importer.py[DEBUG]: Looking for modules ['cc_scripts_user', 'cloudinit.config.cc_scripts_user'] that have attributes ['handle']
Jan 28 15:47:18 one-click-build-test-1453995898-67 [CLOUDINIT] importer.py[DEBUG]: Failed at attempted import of 'cc_scripts_user' due to: No module named cc_scripts_user
Jan 28 15:47:18 one-click-build-test-1453995898-67 [CLOUDINIT] importer.py[DEBUG]: Found cc_scripts_user with attributes ['handle'] in ['cloudinit.config.cc_scripts_user']
Jan 28 15:47:18 one-click-build-test-1453995898-67 [CLOUDINIT] importer.py[DEBUG]: Looking for modules ['cc_ssh_authkey_fingerprints', 'cloudinit.config.cc_ssh_authkey_fingerprints'] that have attributes ['handle']
Jan 28 15:47:18 one-click-build-test-1453995898-67 [CLOUDINIT] importer.py[DEBUG]: Failed at attempted import of 'cc_ssh_authkey_fingerprints' due to: No module named cc_ssh_authkey_fingerprints
Jan 28 15:47:18 one-click-build-test-1453995898-67 [CLOUDINIT] importer.py[DEBUG]: Found cc_ssh_authkey_fingerprints with attributes ['handle'] in ['cloudinit.config.cc_ssh_authkey_fingerprints']
Jan 28 15:47:18 one-click-build-test-1453995898-67 [CLOUDINIT] importer.py[DEBUG]: Looking for modules ['cc_keys_to_console', 'cloudinit.config.cc_keys_to_console'] that have attributes ['handle']
Jan 28 15:47:18 one-click-build-test-1453995898-67 [CLOUDINIT] importer.py[DEBUG]: Failed at attempted import of 'cc_keys_to_console' due to: No module named cc_keys_to_console
Jan 28 15:47:18 one-click-build-test-1453995898-67 [CLOUDINIT] importer.py[DEBUG]: Found cc_keys_to_console with attributes ['handle'] in ['cloudinit.config.cc_keys_to_console']
Jan 28 15:47:18 one-click-build-test-1453995898-67 [CLOUDINIT] importer.py[DEBUG]: Looking for modules ['cc_phone_home', 'cloudinit.config.cc_phone_home'] that have attributes ['handle']
Jan 28 15:47:18 one-click-build-test-1453995898-67 [CLOUDINIT] importer.py[DEBUG]: Failed at attempted import of 'cc_phone_home' due to: No module named cc_phone_home
Jan 28 15:47:18 one-click-build-test-1453995898-67 [CLOUDINIT] importer.py[DEBUG]: Found cc_phone_home with attributes ['handle'] in ['cloudinit.config.cc_phone_home']
Jan 28 15:47:18 one-click-build-test-1453995898-67 [CLOUDINIT] importer.py[DEBUG]: Looking for modules ['cc_final_message', 'cloudinit.config.cc_final_message'] that have attributes ['handle']
Jan 28 15:47:18 one-click-build-test-1453995898-67 [CLOUDINIT] importer.py[DEBUG]: Failed at attempted import of 'cc_final_message' due to: No module named cc_final_message
Jan 28 15:47:18 one-click-build-test-1453995898-67 [CLOUDINIT] importer.py[DEBUG]: Found cc_final_message with attributes ['handle'] in ['cloudinit.config.cc_final_message']
Jan 28 15:47:18 one-click-build-test-1453995898-67 [CLOUDINIT] importer.py[DEBUG]: Looking for modules ['cc_power_state_change', 'cloudinit.config.cc_power_state_change'] that have attributes ['handle']
Jan 28 15:47:18 one-click-build-test-1453995898-67 [CLOUDINIT] importer.py[DEBUG]: Failed at attempted import of 'cc_power_state_change' due to: No module named cc_power_state_change
Jan 28 15:47:18 one-click-build-test-1453995898-67 [CLOUDINIT] importer.py[DEBUG]: Found cc_power_state_change with attributes ['handle'] in ['cloudinit.config.cc_power_state_change']
Jan 28 15:47:18 one-click-build-test-1453995898-67 [CLOUDINIT] importer.py[DEBUG]: Looking for modules ['ubuntu', 'cloudinit.distros.ubuntu'] that have attributes ['Distro']
Jan 28 15:47:18 one-click-build-test-1453995898-67 [CLOUDINIT] importer.py[DEBUG]: Failed at attempted import of 'ubuntu' due to: No module named ubuntu
Jan 28 15:47:18 one-click-build-test-1453995898-67 [CLOUDINIT] importer.py[DEBUG]: Found ubuntu with attributes ['Distro'] in ['cloudinit.distros.ubuntu']
Jan 28 15:47:18 one-click-build-test-1453995898-67 [CLOUDINIT] stages.py[DEBUG]: Using distro class <class 'cloudinit.distros.ubuntu.Distro'>
Jan 28 15:47:18 one-click-build-test-1453995898-67 [CLOUDINIT] util.py[DEBUG]: Writing to /var/lib/cloud/instances/13862411-b73a-4aa1-9735-9ad34e302b41/sem/config_rightscale_userdata - wb: [420] 20 bytes
Jan 28 15:47:18 one-click-build-test-1453995898-67 [CLOUDINIT] helpers.py[DEBUG]: Running config-rightscale_userdata using lock (<FileLock using file '/var/lib/cloud/instances/13862411-b73a-4aa1-9735-9ad34e302b41/sem/config_rightscale_userdata'>)
Jan 28 15:47:18 one-click-build-test-1453995898-67 [CLOUDINIT] cc_rightscale_userdata.py[DEBUG]: Failed to get raw userdata in module rightscale_userdata
Jan 28 15:47:18 one-click-build-test-1453995898-67 [CLOUDINIT] util.py[DEBUG]: Writing to /var/lib/cloud/instances/13862411-b73a-4aa1-9735-9ad34e302b41/sem/config_scripts_vendor - wb: [420] 20 bytes
Jan 28 15:47:18 one-click-build-test-1453995898-67 [CLOUDINIT] helpers.py[DEBUG]: Running config-scripts-vendor using lock (<FileLock using file '/var/lib/cloud/instances/13862411-b73a-4aa1-9735-9ad34e302b41/sem/config_scripts_vendor'>)
Jan 28 15:47:18 one-click-build-test-1453995898-67 [CLOUDINIT] util.py[DEBUG]: Writing to /var/lib/cloud/sem/config_scripts_per_once.once - wb: [420] 20 bytes
Jan 28 15:47:18 one-click-build-test-1453995898-67 [CLOUDINIT] helpers.py[DEBUG]: Running config-scripts-per-once using lock (<FileLock using file '/var/lib/cloud/sem/config_scripts_per_once.once'>)
Jan 28 15:47:18 one-click-build-test-1453995898-67 [CLOUDINIT] helpers.py[DEBUG]: Running config-scripts-per-boot using lock (<cloudinit.helpers.DummyLock object at 0x7f758970f790>)
Jan 28 15:47:18 one-click-build-test-1453995898-67 [CLOUDINIT] util.py[DEBUG]: Writing to /var/lib/cloud/instances/13862411-b73a-4aa1-9735-9ad34e302b41/sem/config_scripts_per_instance - wb: [420] 20 bytes
Jan 28 15:47:18 one-click-build-test-1453995898-67 [CLOUDINIT] helpers.py[DEBUG]: Running config-scripts-per-instance using lock (<FileLock using file '/var/lib/cloud/instances/13862411-b73a-4aa1-9735-9ad34e302b41/sem/config_scripts_per_instance'>)
Jan 28 15:47:18 one-click-build-test-1453995898-67 [CLOUDINIT] util.py[DEBUG]: Writing to /var/lib/cloud/instances/13862411-b73a-4aa1-9735-9ad34e302b41/sem/config_scripts_user - wb: [420] 20 bytes
Jan 28 15:47:18 one-click-build-test-1453995898-67 [CLOUDINIT] helpers.py[DEBUG]: Running config-scripts-user using lock (<FileLock using file '/var/lib/cloud/instances/13862411-b73a-4aa1-9735-9ad34e302b41/sem/config_scripts_user'>)
Jan 28 15:47:18 one-click-build-test-1453995898-67 [CLOUDINIT] util.py[DEBUG]: Running command ['/var/lib/cloud/instance/scripts/userdata'] with allowed return codes [0] (shell=False, capture=False)
Jan 28 15:47:18 one-click-build-test-1453995898-67 [CLOUDINIT] util.py[WARNING]: Failed running /var/lib/cloud/instance/scripts/userdata [-]
Jan 28 15:47:18 one-click-build-test-1453995898-67 [CLOUDINIT] util.py[DEBUG]: Failed running /var/lib/cloud/instance/scripts/userdata [-]#012Traceback (most recent call last):#012  File "/usr/lib/python2.7/dist-packages/cloudinit/util.py", line 644, in runparts#012    subp(prefix + [exe_path], capture=False)#012  File "/usr/lib/python2.7/dist-packages/cloudinit/util.py", line 1559, in subp#012    raise ProcessExecutionError(cmd=args, reason=e)#012ProcessExecutionError: Unexpected error while running command.#012Command: ['/var/lib/cloud/instance/scripts/userdata']#012Exit code: -#012Reason: [Errno 8] Exec format error#012Stdout: ''#012Stderr: ''
Jan 28 15:47:18 one-click-build-test-1453995898-67 [CLOUDINIT] cc_scripts_user.py[WARNING]: Failed to run module scripts-user (scripts in /var/lib/cloud/instance/scripts)
Jan 28 15:47:18 one-click-build-test-1453995898-67 [CLOUDINIT] util.py[WARNING]: Running scripts-user (<module 'cloudinit.config.cc_scripts_user' from '/usr/lib/python2.7/dist-packages/cloudinit/config/cc_scripts_user.pyc'>) failed
Jan 28 15:47:18 one-click-build-test-1453995898-67 [CLOUDINIT] util.py[DEBUG]: Running scripts-user (<module 'cloudinit.config.cc_scripts_user' from '/usr/lib/python2.7/dist-packages/cloudinit/config/cc_scripts_user.pyc'>) failed#012Traceback (most recent call last):#012  File "/usr/lib/python2.7/dist-packages/cloudinit/stages.py", line 658, in _run_modules#012    cc.run(run_name, mod.handle, func_args, freq=freq)#012  File "/usr/lib/python2.7/dist-packages/cloudinit/cloud.py", line 63, in run#012    return self._runners.run(name, functor, args, freq, clear_on_fail)#012  File "/usr/lib/python2.7/dist-packages/cloudinit/helpers.py", line 197, in run#012    results = functor(*args)#012  File "/usr/lib/python2.7/dist-packages/cloudinit/config/cc_scripts_user.py", line 38, in handle#012    util.runparts(runparts_path)#012  File "/usr/lib/python2.7/dist-packages/cloudinit/util.py", line 651, in runparts#012    % (len(failed), len(attempted)))#012RuntimeError: Runparts: 1 failures in 1 attempted commands
Jan 28 15:47:18 one-click-build-test-1453995898-67 [CLOUDINIT] util.py[DEBUG]: Writing to /var/lib/cloud/instances/13862411-b73a-4aa1-9735-9ad34e302b41/sem/config_ssh_authkey_fingerprints - wb: [420] 20 bytes
Jan 28 15:47:18 one-click-build-test-1453995898-67 [CLOUDINIT] helpers.py[DEBUG]: Running config-ssh-authkey-fingerprints using lock (<FileLock using file '/var/lib/cloud/instances/13862411-b73a-4aa1-9735-9ad34e302b41/sem/config_ssh_authkey_fingerprints'>)
Jan 28 15:47:18 one-click-build-test-1453995898-67 [CLOUDINIT] importer.py[DEBUG]: Looking for modules ['cloudinit.mergers.m_list'] that have attributes ['Merger']
Jan 28 15:47:18 one-click-build-test-1453995898-67 [CLOUDINIT] importer.py[DEBUG]: Found m_list with attributes ['Merger'] in ['cloudinit.mergers.m_list']
Jan 28 15:47:18 one-click-build-test-1453995898-67 [CLOUDINIT] importer.py[DEBUG]: Looking for modules ['cloudinit.mergers.m_dict'] that have attributes ['Merger']
Jan 28 15:47:18 one-click-build-test-1453995898-67 [CLOUDINIT] importer.py[DEBUG]: Found m_dict with attributes ['Merger'] in ['cloudinit.mergers.m_dict']
Jan 28 15:47:18 one-click-build-test-1453995898-67 [CLOUDINIT] importer.py[DEBUG]: Looking for modules ['cloudinit.mergers.m_str'] that have attributes ['Merger']
Jan 28 15:47:18 one-click-build-test-1453995898-67 [CLOUDINIT] importer.py[DEBUG]: Found m_str with attributes ['Merger'] in ['cloudinit.mergers.m_str']
Jan 28 15:47:18 one-click-build-test-1453995898-67 [CLOUDINIT] __init__.py[DEBUG]: Merging 'dict' into 'dict' using method '_handle_unknown' of 'LookupMerger: (3)'
Jan 28 15:47:18 one-click-build-test-1453995898-67 [CLOUDINIT] __init__.py[DEBUG]: Merging using located merger 'DictMerger: (method=no_replace,recurse_str=False,recurse_dict=True,recurse_array=False,allow_delete=False)' since it had method '_on_dict'
Jan 28 15:47:18 one-click-build-test-1453995898-67 [CLOUDINIT] importer.py[DEBUG]: Looking for modules ['cloudinit.mergers.m_list'] that have attributes ['Merger']
Jan 28 15:47:18 one-click-build-test-1453995898-67 [CLOUDINIT] importer.py[DEBUG]: Found m_list with attributes ['Merger'] in ['cloudinit.mergers.m_list']
Jan 28 15:47:18 one-click-build-test-1453995898-67 [CLOUDINIT] importer.py[DEBUG]: Looking for modules ['cloudinit.mergers.m_dict'] that have attributes ['Merger']
Jan 28 15:47:18 one-click-build-test-1453995898-67 [CLOUDINIT] importer.py[DEBUG]: Found m_dict with attributes ['Merger'] in ['cloudinit.mergers.m_dict']
Jan 28 15:47:18 one-click-build-test-1453995898-67 [CLOUDINIT] importer.py[DEBUG]: Looking for modules ['cloudinit.mergers.m_str'] that have attributes ['Merger']
Jan 28 15:47:18 one-click-build-test-1453995898-67 [CLOUDINIT] importer.py[DEBUG]: Found m_str with attributes ['Merger'] in ['cloudinit.mergers.m_str']
Jan 28 15:47:18 one-click-build-test-1453995898-67 [CLOUDINIT] __init__.py[DEBUG]: Merging 'dict' into 'dict' using method '_handle_unknown' of 'LookupMerger: (3)'
Jan 28 15:47:18 one-click-build-test-1453995898-67 [CLOUDINIT] __init__.py[DEBUG]: Merging using located merger 'DictMerger: (method=no_replace,recurse_str=False,recurse_dict=True,recurse_array=False,allow_delete=False)' since it had method '_on_dict'
Jan 28 15:47:18 one-click-build-test-1453995898-67 [CLOUDINIT] importer.py[DEBUG]: Looking for modules ['cloudinit.mergers.m_list'] that have attributes ['Merger']
Jan 28 15:47:18 one-click-build-test-1453995898-67 [CLOUDINIT] importer.py[DEBUG]: Found m_list with attributes ['Merger'] in ['cloudinit.mergers.m_list']
Jan 28 15:47:18 one-click-build-test-1453995898-67 [CLOUDINIT] importer.py[DEBUG]: Looking for modules ['cloudinit.mergers.m_dict'] that have attributes ['Merger']
Jan 28 15:47:18 one-click-build-test-1453995898-67 [CLOUDINIT] importer.py[DEBUG]: Found m_dict with attributes ['Merger'] in ['cloudinit.mergers.m_dict']
Jan 28 15:47:18 one-click-build-test-1453995898-67 [CLOUDINIT] importer.py[DEBUG]: Looking for modules ['cloudinit.mergers.m_str'] that have attributes ['Merger']
Jan 28 15:47:18 one-click-build-test-1453995898-67 [CLOUDINIT] importer.py[DEBUG]: Found m_str with attributes ['Merger'] in ['cloudinit.mergers.m_str']
Jan 28 15:47:18 one-click-build-test-1453995898-67 [CLOUDINIT] __init__.py[DEBUG]: Merging 'dict' into 'dict' using method '_handle_unknown' of 'LookupMerger: (3)'
Jan 28 15:47:18 one-click-build-test-1453995898-67 [CLOUDINIT] __init__.py[DEBUG]: Merging using located merger 'DictMerger: (method=no_replace,recurse_str=False,recurse_dict=True,recurse_array=False,allow_delete=False)' since it had method '_on_dict'
Jan 28 15:47:18 one-click-build-test-1453995898-67 [CLOUDINIT] util.py[DEBUG]: Reading from /etc/ssh/sshd_config (quiet=False)
Jan 28 15:47:18 one-click-build-test-1453995898-67 [CLOUDINIT] util.py[DEBUG]: Read 2539 bytes from /etc/ssh/sshd_config
Jan 28 15:47:18 one-click-build-test-1453995898-67 [CLOUDINIT] util.py[DEBUG]: Reading from /home/ubuntu/.ssh/authorized_keys (quiet=False)
Jan 28 15:47:18 one-click-build-test-1453995898-67 [CLOUDINIT] util.py[DEBUG]: Read 399 bytes from /home/ubuntu/.ssh/authorized_keys
Jan 28 15:47:18 one-click-build-test-1453995898-67 [CLOUDINIT] util.py[DEBUG]: Writing to /var/lib/cloud/instances/13862411-b73a-4aa1-9735-9ad34e302b41/sem/config_keys_to_console - wb: [420] 20 bytes
Jan 28 15:47:18 one-click-build-test-1453995898-67 [CLOUDINIT] helpers.py[DEBUG]: Running config-keys-to-console using lock (<FileLock using file '/var/lib/cloud/instances/13862411-b73a-4aa1-9735-9ad34e302b41/sem/config_keys_to_console'>)
Jan 28 15:47:18 one-click-build-test-1453995898-67 [CLOUDINIT] util.py[DEBUG]: Running command ['/usr/lib/cloud-init/write-ssh-key-fingerprints', '', 'ssh-dss'] with allowed return codes [0] (shell=False, capture=True)
Jan 28 15:47:18 one-click-build-test-1453995898-67 [CLOUDINIT] util.py[DEBUG]: Writing to /var/lib/cloud/instances/13862411-b73a-4aa1-9735-9ad34e302b41/sem/config_phone_home - wb: [420] 19 bytes
Jan 28 15:47:18 one-click-build-test-1453995898-67 [CLOUDINIT] helpers.py[DEBUG]: Running config-phone-home using lock (<FileLock using file '/var/lib/cloud/instances/13862411-b73a-4aa1-9735-9ad34e302b41/sem/config_phone_home'>)
Jan 28 15:47:18 one-click-build-test-1453995898-67 [CLOUDINIT] cc_phone_home.py[DEBUG]: Skipping module named phone-home, no 'phone_home' configuration found
Jan 28 15:47:18 one-click-build-test-1453995898-67 [CLOUDINIT] helpers.py[DEBUG]: Running config-final-message using lock (<cloudinit.helpers.DummyLock object at 0x7f75896e9090>)
Jan 28 15:47:18 one-click-build-test-1453995898-67 [CLOUDINIT] util.py[DEBUG]: Reading from /proc/uptime (quiet=False)
Jan 28 15:47:18 one-click-build-test-1453995898-67 [CLOUDINIT] util.py[DEBUG]: Read 12 bytes from /proc/uptime
Jan 28 15:47:19 one-click-build-test-1453995898-67 [CLOUDINIT] util.py[DEBUG]: Cloud-init v. 0.7.5 finished at Thu, 28 Jan 2016 15:47:18 +0000. Datasource DataSourceConfigDriveNet [net,ver=2][source=/dev/xvdd].  Up 23.20 seconds
Jan 28 15:47:19 one-click-build-test-1453995898-67 [CLOUDINIT] util.py[DEBUG]: Writing to /var/lib/cloud/instance/boot-finished - wb: [420] 51 bytes
Jan 28 15:47:19 one-click-build-test-1453995898-67 [CLOUDINIT] util.py[DEBUG]: Writing to /var/lib/cloud/instances/13862411-b73a-4aa1-9735-9ad34e302b41/sem/config_power_state_change - wb: [420] 19 bytes
Jan 28 15:47:19 one-click-build-test-1453995898-67 [CLOUDINIT] helpers.py[DEBUG]: Running config-power-state-change using lock (<FileLock using file '/var/lib/cloud/instances/13862411-b73a-4aa1-9735-9ad34e302b41/sem/config_power_state_change'>)
Jan 28 15:47:19 one-click-build-test-1453995898-67 [CLOUDINIT] cc_power_state_change.py[DEBUG]: no power_state provided. doing nothing
Jan 28 15:47:19 one-click-build-test-1453995898-67 [CLOUDINIT] cloud-init[DEBUG]: Ran 11 modules with 1 failures
Jan 28 15:47:19 one-click-build-test-1453995898-67 [CLOUDINIT] util.py[DEBUG]: Creating symbolic link from '/run/cloud-init/result.json' => '../../var/lib/cloud/data/result.json'
Jan 28 15:47:19 one-click-build-test-1453995898-67 [CLOUDINIT] util.py[DEBUG]: Reading from /proc/uptime (quiet=False)
Jan 28 15:47:19 one-click-build-test-1453995898-67 [CLOUDINIT] util.py[DEBUG]: Read 12 bytes from /proc/uptime
Jan 28 15:47:19 one-click-build-test-1453995898-67 [CLOUDINIT] util.py[DEBUG]: cloud-init mode 'modules' took 0.119 seconds (0.12)
